Workbook

Sheet 01.04
A1: Худудий бўлинмалар ходимлари томонидан ахборот технологиялари соҳасидаги жиноятларни олдини олиш бўйича амалга оширилган ишлар | AP1: Худудий бўлинмалар ходимлари томонидан ахборот технологиялари соҳасидаги жиноятларни олдини олиш бўйича амалга оширилган ишлар
A2: Ҳ И С О Б О Т Ж А Д В А Л И | AP2: ҲИСОБОТ ЖАДВАЛИ
A3: 1-жадвал 01.03.2026 йил | AP3: 2-жадвал 01.03.2026 йил
A4: Худудлар | B4: Ўтказилган учрашувлар сони март ойи учун | AF4: Учрашувда иштирок этган фуқаролар сони | AP4: Худудлар | AQ4: Оммавий ахборот воситаларида чиқишлар сони | BC4: Тарқатилган материаллар | BO4: Суҳбатлар
B5: ЖАМИ | E5: маҳаллалар | H5: олий таълим муассасалари | K5: академик лицейлар | N5: ўрта таълим муассасалари | Q5: мактабгача таълим муассасалари | T5: касалхона ва поликлиника | W5: бозорлар | Z5: ҲМҚОрганлари | AC5: бошқа идора ва ташкилотлар | AF5: ЖАМИ | AH5: учрашувлар давомида | AL5: Онлайн тарғибот давомида
AH6: 18 ёшгача | AJ6: 18 ёшдан катта | AL6: 18 ёшгача | AN6: 18 ёшдан катта | AQ6: Жами | AS6: телевидения | AU6: радио | AW6: газета | AY6: журнал | BA6: интернет (ижтимоий тармоқлар) | BC6: Жами | BE6: Видеоролик ва Кон | BG6: Баннер | BI6: Флаер | BK6: Буклет | BM6: Бошқа | BO6: Пробация рўйғатида турувчи шахслар билан ўтказилган суҳбат
B7: сони | C7: бир кунда | D7: ой бошидан | E7: сони | F7: бир кунда | G7: ой бошидан | H7: сони | I7: бир кунда | J7: ой бошидан | K7: сони | L7: бир кунда | M7: ой бошидан | N7: сони | O7: бир кунда | P7: ой бошидан | Q7: сони | R7: бир кунда | S7: ой бошидан | T7: сони | U7: бир кунда | V7: ой бошидан | W7: сони | X7: бир кунда | Y7: ой бошидан | Z7: сони | AA7: бир кунда | AB7: ой бошидан | AC7: сони | AD7: бир кунда | AE7: ой бошидан | AF7: бир кунда | AG7: ой бошидан | AH7: бир кунда | AI7: ой бошидан | AJ7: бир кунда | AK7: ой бошидан | AL7: бир кунда | AM7: ой бошидан | AN7: бир кунда | AO7: ой бошидан | AQ7: бир кунда | AR7: ой бошидан | AS7: бир кунда | AT7: ой бошидан | AU7: бир кунда | AV7: ой бошидан | AW7: бир кунда | AX7: ой бошидан | AY7: бир кунда | AZ7: ой бошидан | BA7: бир кунда | BB7: ой бошидан | BC7: бир кунда | BD7: ой бошидан | BE7: бир кунда | BF7: ой бошидан | BG7: бир кунда | BH7: ой бошидан | BI7: бир кунда | BJ7: ой бошидан | BK7: бир кунда | BL7: ой бошидан | BM7: бир кунда | BN7: ой бошидан | BO7: Сони | BP7: бир кунда | BQ7: ой бошидан
A8: ИИВ | B8: =E8+H8+K8+N8+Q8+T8+W8+Z8+AC8 -> 0 | C8: =F8+I8+L8+O8+R8+U8+X8+AA8+AD8 -> 0 | D8: =G8+J8+M8+P8+S8+V8+Y8+AB8+AE8 -> 0 | G8: =F8 -> 0 | J8: =I8 -> 0 | M8: =L8 -> 0 | P8: =O8 -> 0 | S8: =R8 -> 0 | V8: =U8 -> 0 | Y8: =X8 -> 0 | AB8: =AA8 -> 0 | AE8: =AD8 -> 0 | AF8: =AH8+AJ8+AL8+AN8 -> 0 | AG8: =AI8+AK8+AM8+AO8 -> 0 | AI8: =AH8 -> 0 | AK8: =AJ8 -> 0 | AM8: =AL8 -> 0 | AO8: =AN8 -> 0 | AP8: ИИВ | AQ8: =AS8+AU8+AW8+AY8+BA8 -> 0 | AR8: =AT8+AV8+AX8+AZ8+BB8 -> 0 | AT8: =AS8 -> 0 | AV8: =AU8 -> 0 | AX8: =AW8 -> 0 | AZ8: =AY8 -> 0 | BB8: =BA8 -> 0 | BC8: =BE8+BG8+BI8+BK8+BM8 -> 0 | BD8: =BF8+BH8+BJ8+BL8+BN8 -> 0 | BF8: =BE8 -> 0 | BH8: =BG8 -> 0 | BJ8: =BI8 -> 0 | BL8: =BK8 -> 0 | BQ8: =BP8 -> 0
A9: ҚКР | B9: =E9+H9+K9+N9+Q9+T9+W9+Z9+AC9 -> 3841 | C9: =F9+I9+L9+O9+R9+U9+X9+AA9+AD9 -> 0 | D9: =G9+J9+M9+P9+S9+V9+Y9+AB9+AE9 -> #REF! | E9: 452 | G9: =F9+#REF! -> #REF! | H9: 12 | J9: =I9+#REF! -> #REF! | K9: 2 | M9: =L9+#REF! -> #REF! | N9: 735 | P9: =O9+#REF! -> #REF! | Q9: 502 | S9: =R9+#REF! -> #REF! | T9: 197 | V9: =U9+#REF! -> #REF! | W9: 47 | Y9: =X9+#REF! -> #REF! | Z9: 34 | AB9: =AA9+#REF! -> #REF! | AC9: 1860 | AE9: =AD9+#REF! -> #REF! | AF9: 0 | AG9: 0 | AI9: =AH9+#REF! -> #REF! | AK9: =AJ9+#REF! -> #REF! | AM9: =AL9+#REF! -> #REF! | AO9: =AN9+#REF! -> #REF! | AP9: ҚКР | AQ9: 0 | AR9: 0 | AT9: =AS9+#REF! -> #REF! | AV9: =AU9+#REF! -> #REF! | AX9: =AW9+#REF! -> #REF! | AZ9: =AY9+#REF! -> #REF! | BB9: =BA9+#REF! -> #REF! | BC9: 0 | BD9: 0 | BF9: =BE9+#REF! -> #REF! | BH9: =BG9+#REF! -> #REF! | BJ9: =BI9+#REF! -> #REF! | BL9: =BK9+#REF! -> #REF! | BN9: =BM9+#REF! -> #REF! | BO9: 14 | BQ9: =BP9+#REF! -> #REF!
A10: Тошкент шаҳри | B10: =E10+H10+K10+N10+Q10+T10+W10+Z10+AC10 -> 3627 | C10: =F10+I10+L10+O10+R10+U10+X10+AA10+AD10 -> 0 | D10: =G10+J10+M10+P10+S10+V10+Y10+AB10+AE10 -> #REF! | E10: 585 | F10: 0 | G10: =F10+#REF! -> #REF! | H10: 93 | I10: 0 | J10: =I10+#REF! -> #REF! | K10: 34 | L10: 0 | M10: =L10+#REF! -> #REF! | N10: 352 | O10: 0 | P10: =O10+#REF! -> #REF! | Q10: 549 | R10: 0 | S10: =R10+#REF! -> #REF! | T10: 198 | U10: 0 | V10: =U10+#REF! -> #REF! | W10: 55 | X10: 0 | Y10: =X10+#REF! -> #REF! | Z10: 71 | AA10: 0 | AB10: =AA10+#REF! -> #REF! | AC10: 1690 | AD10: 0 | AE10: =AD10+#REF! -> #REF! | AF10: 0 | AG10: 0 | AH10: 0 | AI10: =AH10+#REF! -> #REF! | AJ10: 0 | AK10: =AJ10+#REF! -> #REF! | AL10: 0 | AM10: =AL10+#REF! -> #REF! | AN10: 0 | AO10: =AN10+#REF! -> #REF! | AP10: Тошкент шаҳри | AQ10: 0 | AR10: 0 | AS10: 0 | AT10: =AS10+#REF! -> #REF! | AU10: 0 | AV10: =AU10+#REF! -> #REF! | AW10: 0 | AX10: =AW10+#REF! -> #REF! | AY10: 0 | AZ10: =AY10+#REF! -> #REF! | BA10: 0 | BB10: =BA10+#REF! -> #REF! | BC10: 0 | BD10: 0 | BE10: 0 | BF10: =BE10+#REF! -> #REF! | BG10: 0 | BH10: =BG10+#REF! -> #REF! | BI10: 0 | BJ10: =BI10+#REF! -> #REF! | BK10: 0 | BL10: =BK10+#REF! -> #REF! | BM10: 0 | BN10: =BM10+#REF! -> #REF! | BO10: 32 | BP10: 0 | BQ10: =BP10+#REF! -> #REF!
A11: Тошкент вилояти | B11: =E11+H11+K11+N11+Q11+T11+W11+Z11+AC11 -> 15381 | C11: =F11+I11+L11+O11+R11+U11+X11+AA11+AD11 -> 155 | D11: =G11+J11+M11+P11+S11+V11+Y11+AB11+AE11 -> #REF! | E11: 883 | F11: 55 | G11: =F11+#REF! -> #REF! | H11: 16 | I11: 0 | J11: =I11+#REF! -> #REF! | K11: 3 | L11: 0 | M11: =L11+#REF! -> #REF! | N11: 875 | O11: 0 | P11: =O11+#REF! -> #REF! | Q11: 2424 | R11: 0 | S11: =R11+#REF! -> #REF! | T11: 69 | U11: 0 | V11: =U11+#REF! -> #REF! | W11: 133 | X11: 91 | Y11: =X11+#REF! -> #REF! | Z11: 1116 | AA11: 0 | AB11: =AA11+#REF! -> #REF! | AC11: 9862 | AD11: 9 | AE11: =AD11+#REF! -> #REF! | AF11: 173200 | AG11: 173200 | AH11: 6200 | AI11: =AH11+#REF! -> #REF! | AJ11: 9000 | AK11: =AJ11+#REF! -> #REF! | AL11: 53000 | AM11: =AL11+#REF! -> #REF! | AN11: 105000 | AO11: =AN11+#REF! -> #REF! | AP11: Тошкент вилояти | AQ11: 11 | AR11: 11 | AS11: 0 | AT11: =AS11+#REF! -> #REF! | AU11: 0 | AV11: =AU11+#REF! -> #REF! | AW11: 0 | AX11: =AW11+#REF! -> #REF! | AY11: 0 | AZ11: =AY11+#REF! -> #REF! | BA11: 11 | BB11: =BA11+#REF! -> #REF! | BC11: 6343 | BD11: 6343 | BE11: 12 | BF11: =BE11+#REF! -> #REF! | BG11: 6 | BH11: =BG11+#REF! -> #REF! | BI11: 6200 | BJ11: =BI11+#REF! -> #REF! | BK11: 125 | BL11: =BK11+#REF! -> #REF! | BM11: 0 | BN11: =BM11+#REF! -> #REF! | BO11: 11506 | BP11: 8 | BQ11: =BP11+#REF! -> #REF!
A12: Андижон вилояти | B12: =E12+H12+K12+N12+Q12+T12+W12+Z12+AC12 -> 30164 | C12: =F12+I12+L12+O12+R12+U12+X12+AA12+AD12 -> 237 | D12: =G12+J12+M12+P12+S12+V12+Y12+AB12+AE12 -> #REF! | E12: 909 | F12: 48 | G12: =F12+#REF! -> #REF! | H12: 80 | I12: 5 | J12: =I12+#REF! -> #REF! | K12: 5 | L12: 0 | M12: =L12+#REF! -> #REF! | N12: 820 | O12: 22 | P12: =O12+#REF! -> #REF! | Q12: 549 | R12: 0 | S12: =R12+#REF! -> #REF! | T12: 992 | U12: 0 | V12: =U12+#REF! -> #REF! | W12: 38 | X12: 131 | Y12: =X12+#REF! -> #REF! | Z12: 68 | AA12: 0 | AB12: =AA12+#REF! -> #REF! | AC12: 26703 | AD12: 31 | AE12: =AD12+#REF! -> #REF! | AF12: 30200 | AG12: 30200 | AH12: 8000 | AI12: =AH12+#REF! -> #REF! | AJ12: 9500 | AK12: =AJ12+#REF! -> #REF! | AL12: 6350 | AM12: =AL12+#REF! -> #REF! | AN12: 6350 | AO12: =AN12+#REF! -> #REF! | AP12: Андижон вилояти | AQ12: 128 | AR12: 128 | AS12: 0 | AT12: =AS12+#REF! -> #REF! | AU12: 0 | AV12: =AU12+#REF! -> #REF! | AW12: 0 | AX12: =AW12+#REF! -> #REF! | AY12: 0 | AZ12: =AY12+#REF! -> #REF! | BA12: 128 | BB12: =BA12+#REF! -> #REF! | BC12: 3802 | BD12: 3802 | BE12: 89 | BF12: =BE12+#REF! -> #REF! | BG12: 13 | BH12: =BG12+#REF! -> #REF! | BI12: 3200 | BJ12: =BI12+#REF! -> #REF! | BK12: 500 | BL12: =BK12+#REF! -> #REF! | BM12: 0 | BN12: =BM12+#REF! -> #REF! | BP12: 2 | BQ12: =BP12+#REF! -> #REF!
A13: Бухоро вилояти | B13: =E13+H13+K13+N13+Q13+T13+W13+Z13+AC13 -> 2044 | C13: =F13+I13+L13+O13+R13+U13+X13+AA13+AD13 -> 5 | D13: =G13+J13+M13+P13+S13+V13+Y13+AB13+AE13 -> #REF! | E13: 516 | F13: 2 | G13: =F13+#REF! -> #REF! | H13: 10 | I13: 0 | J13: =I13+#REF! -> #REF! | K13: 38 | L13: 0 | M13: =L13+#REF! -> #REF! | N13: 581 | O13: 1 | P13: =O13+#REF! -> #REF! | Q13: 525 | R13: 0 | S13: =R13+#REF! -> #REF! | T13: 263 | U13: 0 | V13: =U13+#REF! -> #REF! | W13: 43 | X13: 0 | Y13: =X13+#REF! -> #REF! | Z13: 17 | AA13: 0 | AB13: =AA13+#REF! -> #REF! | AC13: 51 | AD13: 2 | AE13: =AD13+#REF! -> #REF! | AF13: 228000 | AG13: 228000 | AH13: 700 | AI13: =AH13+#REF! -> #REF! | AJ13: 7300 | AK13: =AJ13+#REF! -> #REF! | AL13: 20000 | AM13: =AL13+#REF! -> #REF! | AN13: 200000 | AO13: =AN13+#REF! -> #REF! | AP13: Бухоро вилояти | AQ13: 12 | AR13: 12 | AS13: 1 | AT13: =AS13+#REF! -> #REF! | AU13: 1 | AV13: =AU13+#REF! -> #REF! | AW13: 0 | AX13: =AW13+#REF! -> #REF! | AY13: 0 | AZ13: =AY13+#REF! -> #REF! | BA13: 10 | BB13: =BA13+#REF! -> #REF! | BC13: 8304 | BD13: 8304 | BE13: 200 | BF13: =BE13+#REF! -> #REF! | BG13: 4 | BH13: =BG13+#REF! -> #REF! | BI13: 8000 | BJ13: =BI13+#REF! -> #REF! | BK13: 100 | BL13: =BK13+#REF! -> #REF! | BM13: 0 | BN13: =BM13+#REF! -> #REF! | BP13: 1 | BQ13: =BP13+#REF! -> #REF!
A14: Жиззах вилояти | B14: =E14+H14+K14+N14+Q14+T14+W14+Z14+AC14 -> 3916 | C14: =F14+I14+L14+O14+R14+U14+X14+AA14+AD14 -> 146 | D14: =G14+J14+M14+P14+S14+V14+Y14+AB14+AE14 -> #REF! | E14: 304 | F14: 117 | G14: =F14+#REF! -> #REF! | H14: 5 | I14: 0 | J14: =I14+#REF! -> #REF! | K14: 34 | L14: 0 | M14: =L14+#REF! -> #REF! | N14: 583 | O14: 0 | P14: =O14+#REF! -> #REF! | Q14: 254 | R14: 0 | S14: =R14+#REF! -> #REF! | T14: 196 | U14: 0 | V14: =U14+#REF! -> #REF! | W14: 30 | X14: 25 | Y14: =X14+#REF! -> #REF! | Z14: 10 | AA14: 0 | AB14: =AA14+#REF! -> #REF! | AC14: 2500 | AD14: 4 | AE14: =AD14+#REF! -> #REF! | AF14: 190290 | AG14: 190290 | AH14: 1420 | AI14: =AH14+#REF! -> #REF! | AJ14: 12520 | AK14: =AJ14+#REF! -> #REF! | AL14: 11220 | AM14: =AL14+#REF! -> #REF! | AN14: 165130 | AO14: =AN14+#REF! -> #REF! | AP14: Жиззах вилояти | AQ14: 12 | AR14: 12 | AS14: 1 | AT14: =AS14+#REF! -> #REF! | AU14: 0 | AV14: =AU14+#REF! -> #REF! | AW14: 1 | AX14: =AW14+#REF! -> #REF! | AY14: 0 | AZ14: =AY14+#REF! -> #REF! | BA14: 10 | BB14: =BA14+#REF! -> #REF! | BC14: 5302 | BD14: 5302 | BE14: 12 | BF14: =BE14+#REF! -> #REF! | BG14: 5 | BH14: =BG14+#REF! -> #REF! | BI14: 5240 | BJ14: =BI14+#REF! -> #REF! | BK14: 45 | BL14: =BK14+#REF! -> #REF! | BM14: 0 | BN14: =BM14+#REF! -> #REF! | BO14: 2 | BP14: 1 | BQ14: =BP14+#REF! -> #REF!
A15: Қашқадарё вилояти | B15: =E15+H15+K15+N15+Q15+T15+W15+Z15+AC15 -> 3897 | C15: =F15+I15+L15+O15+R15+U15+X15+AA15+AD15 -> 496 | D15: =G15+J15+M15+P15+S15+V15+Y15+AB15+AE15 -> #REF! | E15: 776 | F15: 316 | G15: =F15+#REF! -> #REF! | H15: 9 | I15: 0 | J15: =I15+#REF! -> #REF! | K15: 6 | L15: 0 | M15: =L15+#REF! -> #REF! | N15: 1305 | O15: 0 | P15: =O15+#REF! -> #REF! | Q15: 447 | R15: 0 | S15: =R15+#REF! -> #REF! | T15: 337 | U15: 0 | V15: =U15+#REF! -> #REF! | W15: 78 | X15: 0 | Y15: =X15+#REF! -> #REF! | Z15: 141 | AA15: 0 | AB15: =AA15+#REF! -> #REF! | AC15: 798 | AD15: 180 | AE15: =AD15+#REF! -> #REF! | AF15: 1571173 | AG15: 1565673 | AH15: 1049 | AI15: =AH15+#REF! -> #REF! | AJ15: 5500 | AK15: =AJ15+#REF! -> #REF! | AL15: 782312 | AM15: =AL15+#REF! -> #REF! | AN15: 782312 | AO15: =AN15+#REF! -> #REF! | AP15: Қашқадарё вилояти | AQ15: 4 | AR15: 4 | AS15: 0 | AT15: =AS15+#REF! -> #REF! | AU15: 0 | AV15: =AU15+#REF! -> #REF! | AW15: 0 | AX15: =AW15+#REF! -> #REF! | AY15: 0 | AZ15: =AY15+#REF! -> #REF! | BA15: 4 | BB15: =BA15+#REF! -> #REF! | BC15: 4494 | BD15: 4494 | BE15: 88 | BF15: =BE15+#REF! -> #REF! | BG15: 6 | BH15: =BG15+#REF! -> #REF! | BI15: 2200 | BJ15: =BI15+#REF! -> #REF! | BK15: 2200 | BL15: =BK15+#REF! -> #REF! | BM15: 0 | BN15: =BM15+#REF! -> #REF! | BO15: 6274 | BP15: 2 | BQ15: =BP15+#REF! -> #REF! | BR15: умумий утирганлар билан
A16: Навоий вилояти | B16: =E16+H16+K16+N16+Q16+T16+W16+Z16+AC16 -> 19901 | C16: =F16+I16+L16+O16+R16+U16+X16+AA16+AD16 -> 154 | D16: =G16+J16+M16+P16+S16+V16+Y16+AB16+AE16 -> #REF! | E16: 310 | F16: 61 | G16: =F16+#REF! -> #REF! | H16: 5 | I16: 0 | J16: =I16+#REF! -> #REF! | K16: 3 | L16: 0 | M16: =L16+#REF! -> #REF! | N16: 384 | O16: 0 | P16: =O16+#REF! -> #REF! | Q16: 245 | R16: 0 | S16: =R16+#REF! -> #REF! | T16: 397 | U16: 0 | V16: =U16+#REF! -> #REF! | W16: 24 | X16: 36 | Y16: =X16+#REF! -> #REF! | Z16: 18 | AA16: 0 | AB16: =AA16+#REF! -> #REF! | AC16: 18515 | AD16: 57 | AE16: =AD16+#REF! -> #REF! | AF16: 65462 | AG16: 65462 | AH16: 316 | AI16: =AH16+#REF! -> #REF! | AJ16: 1226 | AK16: =AJ16+#REF! -> #REF! | AL16: 4230 | AM16: =AL16+#REF! -> #REF! | AN16: 59690 | AO16: =AN16+#REF! -> #REF! | AP16: Навоий вилояти | AQ16: 75 | AR16: 75 | AS16: 0 | AT16: =AS16+#REF! -> #REF! | AU16: 0 | AV16: =AU16+#REF! -> #REF! | AW16: 0 | AX16: =AW16+#REF! -> #REF! | AY16: 0 | AZ16: =AY16+#REF! -> #REF! | BA16: 75 | BB16: =BA16+#REF! -> #REF! | BC16: 1567 | BD16: 1567 | BE16: 85 | BF16: =BE16+#REF! -> #REF! | BG16: 2 | BH16: =BG16+#REF! -> #REF! | BI16: 1230 | BJ16: =BI16+#REF! -> #REF! | BK16: 250 | BL16: =BK16+#REF! -> #REF! | BM16: 0 | BN16: =BM16+#REF! -> #REF! | BO16: 2546 | BP16: 0 | BQ16: =BP16+#REF! -> #REF!
A17: Наманган вилояти | B17: =E17+H17+K17+N17+Q17+T17+W17+Z17+AC17 -> 5602 | C17: =F17+I17+L17+O17+R17+U17+X17+AA17+AD17 -> 156 | D17: =G17+J17+M17+P17+S17+V17+Y17+AB17+AE17 -> #REF! | E17: 754 | F17: 86 | G17: =F17+#REF! -> #REF! | H17: 9 | I17: 0 | J17: =I17+#REF! -> #REF! | K17: 5 | L17: 0 | M17: =L17+#REF! -> #REF! | N17: 768 | O17: 0 | P17: =O17+#REF! -> #REF! | Q17: 624 | R17: 0 | S17: =R17+#REF! -> #REF! | T17: 742 | U17: 0 | V17: =U17+#REF! -> #REF! | W17: 54 | X17: 0 | Y17: =X17+#REF! -> #REF! | Z17: 66 | AA17: 0 | AB17: =AA17+#REF! -> #REF! | AC17: 2580 | AD17: 70 | AE17: =AD17+#REF! -> #REF! | AF17: 174300 | AG17: 174300 | AH17: 9500 | AI17: =AH17+#REF! -> #REF! | AJ17: 9800 | AK17: =AJ17+#REF! -> #REF! | AL17: 80000 | AM17: =AL17+#REF! -> #REF! | AN17: 75000 | AO17: =AN17+#REF! -> #REF! | AP17: Наманган вилояти | AQ17: 15 | AR17: 15 | AS17: 1 | AT17: =AS17+#REF! -> #REF! | AU17: 0 | AV17: =AU17+#REF! -> #REF! | AW17: 0 | AX17: =AW17+#REF! -> #REF! | AY17: 0 | AZ17: =AY17+#REF! -> #REF! | BA17: 14 | BB17: =BA17+#REF! -> #REF! | BC17: 1392 | BD17: 1392 | BE17: 38 | BF17: =BE17+#REF! -> #REF! | BG17: 4 | BH17: =BG17+#REF! -> #REF! | BI17: 1200 | BJ17: =BI17+#REF! -> #REF! | BK17: 150 | BL17: =BK17+#REF! -> #REF! | BM17: 0 | BN17: =BM17+#REF! -> #REF! | BO17: 8022 | BP17: 0 | BQ17: =BP17+#REF! -> #REF!
A18: Самарқанд вилояти | B18: =E18+H18+K18+N18+Q18+T18+W18+Z18+AC18 -> 3791 | C18: =F18+I18+L18+O18+R18+U18+X18+AA18+AD18 -> 584 | D18: =G18+J18+M18+P18+S18+V18+Y18+AB18+AE18 -> #REF! | E18: 1063 | F18: 411 | G18: =F18+#REF! -> #REF! | H18: 19 | I18: 0 | J18: =I18+#REF! -> #REF! | K18: 8 | L18: 0 | M18: =L18+#REF! -> #REF! | N18: 1331 | O18: 0 | P18: =O18+#REF! -> #REF! | Q18: 777 | R18: 0 | S18: =R18+#REF! -> #REF! | T18: 318 | U18: 0 | V18: =U18+#REF! -> #REF! | W18: 60 | X18: 173 | Y18: =X18+#REF! -> #REF! | Z18: 72 | AA18: 0 | AB18: =AA18+#REF! -> #REF! | AC18: 143 | AD18: 0 | AE18: =AD18+#REF! -> #REF! | AF18: 418649 | AG18: 418649 | AH18: 1210 | AI18: =AH18+#REF! -> #REF! | AJ18: 6014 | AK18: =AJ18+#REF! -> #REF! | AL18: 17255 | AM18: =AL18+#REF! -> #REF! | AN18: 394170 | AO18: =AN18+#REF! -> #REF! | AP18: Самарқанд вилояти | AQ18: 16 | AR18: 16 | AS18: 1 | AT18: =AS18+#REF! -> #REF! | AU18: 0 | AV18: =AU18+#REF! -> #REF! | AW18: 0 | AX18: =AW18+#REF! -> #REF! | AY18: 0 | AZ18: =AY18+#REF! -> #REF! | BA18: 15 | BB18: =BA18+#REF! -> #REF! | BC18: 5569 | BD18: 5569 | BE18: 0 | BF18: =BE18+#REF! -> #REF! | BG18: 0 | BH18: =BG18+#REF! -> #REF! | BI18: 5215 | BJ18: =BI18+#REF! -> #REF! | BK18: 354 | BL18: =BK18+#REF! -> #REF! | BM18: 0 | BN18: =BM18+#REF! -> #REF! | BO18: 442 | BP18: 0 | BQ18: =BP18+#REF! -> #REF!
A19: Сирдарё вилояти | B19: =E19+H19+K19+N19+Q19+T19+W19+Z19+AC19 -> 1040 | C19: =F19+I19+L19+O19+R19+U19+X19+AA19+AD19 -> 28 | D19: =G19+J19+M19+P19+S19+V19+Y19+AB19+AE19 -> #REF! | E19: 221 | F19: 8 | G19: =F19+#REF! -> #REF! | H19: 5 | I19: 0 | J19: =I19+#REF! -> #REF! | K19: 4 | L19: 0 | M19: =L19+#REF! -> #REF! | N19: 313 | O19: 0 | P19: =O19+#REF! -> #REF! | Q19: 203 | R19: 0 | S19: =R19+#REF! -> #REF! | T19: 241 | U19: 0 | V19: =U19+#REF! -> #REF! | W19: 14 | X19: 7 | Y19: =X19+#REF! -> #REF! | Z19: 7 | AA19: 0 | AB19: =AA19+#REF! -> #REF! | AC19: 32 | AD19: 13 | AE19: =AD19+#REF! -> #REF! | AF19: 4000 | AG19: 4000 | AH19: 600 | AI19: =AH19+#REF! -> #REF! | AJ19: 600 | AK19: =AJ19+#REF! -> #REF! | AL19: 1400 | AM19: =AL19+#REF! -> #REF! | AN19: 1400 | AO19: =AN19+#REF! -> #REF! | AP19: Сирдарё вилояти | AQ19: 0 | AR19: 0 | AT19: =AS19+#REF! -> #REF! | AV19: =AU19+#REF! -> #REF! | AX19: =AW19+#REF! -> #REF! | AZ19: =AY19+#REF! -> #REF! | BB19: =BA19+#REF! -> #REF! | BC19: 0 | BD19: 0 | BF19: =BE19+#REF! -> #REF! | BH19: =BG19+#REF! -> #REF! | BJ19: =BI19+#REF! -> #REF! | BL19: =BK19+#REF! -> #REF! | BN19: =BM19+#REF! -> #REF! | BO19: 2898 | BQ19: =BP19+#REF! -> #REF!
A20: Сурхондарё вилояти | B20: =E20+H20+K20+N20+Q20+T20+W20+Z20+AC20 -> 5228 | C20: =F20+I20+L20+O20+R20+U20+X20+AA20+AD20 -> 375 | D20: =G20+J20+M20+P20+S20+V20+Y20+AB20+AE20 -> #REF! | E20: 723 | F20: 219 | G20: =F20+#REF! -> #REF! | H20: 5 | I20: 1 | J20: =I20+#REF! -> #REF! | K20: 3 | L20: 0 | M20: =L20+#REF! -> #REF! | N20: 975 | O20: 80 | P20: =O20+#REF! -> #REF! | Q20: 1862 | R20: 4 | S20: =R20+#REF! -> #REF! | T20: 35 | U20: 4 | V20: =U20+#REF! -> #REF! | W20: 64 | X20: 6 | Y20: =X20+#REF! -> #REF! | Z20: 15 | AA20: 1 | AB20: =AA20+#REF! -> #REF! | AC20: 1546 | AD20: 60 | AE20: =AD20+#REF! -> #REF! | AF20: 13980 | AG20: 13980 | AH20: 5890 | AI20: =AH20+#REF! -> #REF! | AJ20: 7490 | AK20: =AJ20+#REF! -> #REF! | AL20: 450 | AM20: =AL20+#REF! -> #REF! | AN20: 150 | AO20: =AN20+#REF! -> #REF! | AP20: Сурхондарё вилояти | AQ20: 258 | AR20: 258 | AS20: 1 | AT20: =AS20+#REF! -> #REF! | AU20: 1 | AV20: =AU20+#REF! -> #REF! | AW20: 1 | AX20: =AW20+#REF! -> #REF! | AZ20: =AY20+#REF! -> #REF! | BA20: 255 | BB20: =BA20+#REF! -> #REF! | BC20: 2544 | BD20: 2544 | BE20: 4 | BF20: =BE20+#REF! -> #REF! | BH20: =BG20+#REF! -> #REF! | BI20: 1250 | BJ20: =BI20+#REF! -> #REF! | BK20: 1290 | BL20: =BK20+#REF! -> #REF! | BN20: =BM20+#REF! -> #REF! | BO20: 5854 | BQ20: =BP20+#REF! -> #REF! | BR20: 1862 та давлатники | BU20: 1302 та хусусий
A21: Фарғона | B21: =E21+H21+K21+N21+Q21+T21+W21+Z21+AC21 -> 3266 | C21: =F21+I21+L21+O21+R21+U21+X21+AA21+AD21 -> 226 | D21: =G21+J21+M21+P21+S21+V21+Y21+AB21+AE21 -> #REF! | E21: 1017 | F21: 220 | G21: =F21+#REF! -> #REF! | H21: 8 | I21: 5 | J21: =I21+#REF! -> #REF! | K21: 4 | L21: 0 | M21: =L21+#REF! -> #REF! | N21: 963 | O21: 0 | P21: =O21+#REF! -> #REF! | Q21: 912 | R21: 0 | S21: =R21+#REF! -> #REF! | T21: 199 | U21: 0 | V21: =U21+#REF! -> #REF! | W21: 101 | X21: 0 | Y21: =X21+#REF! -> #REF! | Z21: 42 | AA21: 0 | AB21: =AA21+#REF! -> #REF! | AC21: 20 | AD21: 1 | AE21: =AD21+#REF! -> #REF! | AF21: 260000 | AG21: 260000 | AH21: 2000 | AI21: =AH21+#REF! -> #REF! | AJ21: 58000 | AK21: =AJ21+#REF! -> #REF! | AL21: 10000 | AM21: =AL21+#REF! -> #REF! | AN21: 190000 | AO21: =AN21+#REF! -> #REF! | AP21: Фарғона | AQ21: 12 | AR21: 12 | AS21: 1 | AT21: =AS21+#REF! -> #REF! | AU21: 4 | AV21: =AU21+#REF! -> #REF! | AW21: 1 | AX21: =AW21+#REF! -> #REF! | AY21: 0 | AZ21: =AY21+#REF! -> #REF! | BA21: 6 | BB21: =BA21+#REF! -> #REF! | BC21: 9 | BD21: 9 | BE21: 4 | BF21: =BE21+#REF! -> #REF! | BG21: 0 | BH21: =BG21+#REF! -> #REF! | BI21: 4 | BJ21: =BI21+#REF! -> #REF! | BK21: 0 | BL21: =BK21+#REF! -> #REF! | BM21: 1 | BN21: =BM21+#REF! -> #REF! | BQ21: =BP21+#REF! -> #REF!
A22: Хоразм | B22: =E22+H22+K22+N22+Q22+T22+W22+Z22+AC22 -> 1787 | C22: =F22+I22+L22+O22+R22+U22+X22+AA22+AD22 -> 1953 | D22: =G22+J22+M22+P22+S22+V22+Y22+AB22+AE22 -> #REF! | E22: 509 | F22: 422 | G22: =F22+#REF! -> #REF! | H22: 8 | I22: 241 | J22: =I22+#REF! -> #REF! | K22: 21 | M22: =L22+#REF! -> #REF! | N22: 560 | P22: =O22+#REF! -> #REF! | Q22: 375 | S22: =R22+#REF! -> #REF! | T22: 165 | U22: 42 | V22: =U22+#REF! -> #REF! | W22: 28 | X22: 90 | Y22: =X22+#REF! -> #REF! | Z22: 9 | AB22: =AA22+#REF! -> #REF! | AC22: 112 | AD22: 1158 | AE22: =AD22+#REF! -> #REF! | AF22: 993563 | AG22: 993563 | AH22: 784 | AI22: =AH22+#REF! -> #REF! | AJ22: 7238 | AK22: =AJ22+#REF! -> #REF! | AL22: 5412 | AM22: =AL22+#REF! -> #REF! | AN22: 980129 | AO22: =AN22+#REF! -> #REF! | AP22: Хоразм | AQ22: 635 | AR22: 635 | AT22: =AS22+#REF! -> #REF! | AV22: =AU22+#REF! -> #REF! | AX22: =AW22+#REF! -> #REF! | AZ22: =AY22+#REF! -> #REF! | BA22: 635 | BB22: =BA22+#REF! -> #REF! | BC22: 6489 | BD22: 6489 | BE22: 31 | BF22: =BE22+#REF! -> #REF! | BH22: =BG22+#REF! -> #REF! | BI22: 6400 | BJ22: =BI22+#REF! -> #REF! | BK22: 58 | BL22: =BK22+#REF! -> #REF! | BN22: =BM22+#REF! -> #REF! | BO22: 26 | BP22: 226 | BQ22: =BP22+#REF! -> #REF!
A23: ЖАМИ | B23: =E23+H23+K23+N23+Q23+T23+W23+Z23+AC23 -> 94991 | C23: =F23+I23+L23+O23+R23+U23+X23+AA23+AD23 -> 4515 | D23: =G23+J23+M23+P23+S23+V23+Y23+AB23+AE23 -> #REF! | E23: =+E18+E19+E22+E17+E16+E15+E14+E13+E12+E11+E10+E9+E8 -> 7282 | F23: =SUM(F8:F22) -> 1965 | G23: =SUM(G8:G22) -> #REF! | H23: =+H18+H19+H22+H17+H16+H15+H14+H13+H12+H11+H10+H9+H8 -> 271 | I23: =SUM(I8:I22) -> 252 | J23: =SUM(J8:J22) -> #REF! | K23: =+K18+K19+K22+K17+K16+K15+K14+K13+K12+K11+K10+K9+K8 -> 163 | L23: =SUM(L8:L22) -> 0 | M23: =SUM(M8:M22) -> #REF! | N23: =+N18+N19+N22+N17+N16+N15+N14+N13+N12+N11+N10+N9+N8 -> 8607 | O23: =SUM(O8:O22) -> 103 | P23: =SUM(P8:P22) -> #REF! | Q23: =+Q18+Q19+Q22+Q17+Q16+Q15+Q14+Q13+Q12+Q11+Q10+Q9+Q8 -> 7474 | R23: =SUM(R8:R22) -> 4 | S23: =SUM(S8:S22) -> #REF! | T23: =+T18+T19+T22+T17+T16+T15+T14+T13+T12+T11+T10+T9+T8 -> 4115 | U23: =SUM(U8:U22) -> 46 | V23: =SUM(V8:V22) -> #REF! | W23: =+W18+W19+W22+W17+W16+W15+W14+W13+W12+W11+W10+W9+W8 -> 604 | X23: =SUM(X8:X22) -> 559 | Y23: =SUM(Y8:Y22) -> #REF! | Z23: =+Z18+Z19+Z22+Z17+Z16+Z15+Z14+Z13+Z12+Z11+Z10+Z9+Z8 -> 1629 | AA23: =SUM(AA8:AA22) -> 1 | AB23: =SUM(AB8:AB22) -> #REF! | AC23: =+AC18+AC19+AC22+AC17+AC16+AC15+AC14+AC13+AC12+AC11+AC10+AC9+AC8 -> 64846 | AD23: =SUM(AD8:AD22) -> 1585 | AE23: =SUM(AE8:AE22) -> #REF! | AF23: =SUM(AF8:AF22) -> 4122817 | AG23: =SUM(AG8:AG22) -> 4117317 | AH23: =SUM(AH8:AH22) -> 37669 | AI23: =SUM(AI8:AI22) -> #REF! | AJ23: =SUM(AJ8:AJ22) -> 134188 | AK23: =SUM(AK8:AK22) -> #REF! | ... AO23: =SUM(AO8:AO22) -> #REF! | AP23: ЖАМИ | AQ23: =SUM(AQ8:AQ22) -> 1178 | AR23: =SUM(AR8:AR22) -> 1178 | AS23: =SUM(AS8:AS22) -> 6 | AT23: =SUM(AT8:AT22) -> #REF! | AU23: =SUM(AU8:AU22) -> 6 | AV23: =SUM(AV8:AV22) -> #REF! | AW23: =SUM(AW8:AW22) -> 3 | AX23: =SUM(AX8:AX22) -> #REF! | ... BQ23: =SUM(BQ8:BQ22) -> #REF!

Sheet 01.04.
A1: Худудий бўлинмалар ходимлари томонидан ахборот технологиялари соҳасидаги жиноятларни олдини олиш бўйича амалга оширилган ишлар | AP1: Худудий бўлинмалар ходимлари томонидан ахборот технологиялари соҳасидаги жиноятларни олдини олиш бўйича амалга оширилган ишлар
A2: Ҳ И С О Б О Т Ж А Д В А Л И | AP2: ҲИСОБОТ ЖАДВАЛИ
A3: 1-жадвал 01.03.2026 йил | AP3: 2-жадвал 01.03.2026 йил
A4: Худудлар | B4: Ўтказилган учрашувлар сони март ойи учун | AF4: Учрашувда иштирок этган фуқаролар сони | AP4: Худудлар | AQ4: Оммавий ахборот воситаларида чиқишлар сони | BC4: Тарқатилган материаллар | BO4: Суҳбатлар
B5: ЖАМИ | E5: маҳаллалар | H5: олий таълим муассасалари | K5: академик лицейлар | N5: ўрта таълим муассасалари | Q5: мактабгача таълим муассасалари | T5: касалхона ва поликлиника | W5: бозорлар | Z5: ҲМҚОрганлари | AC5: бошқа идора ва ташкилотлар | AF5: ЖАМИ | AH5: учрашувлар давомида | AL5: Онлайн тарғибот давомида
AH6: 18 ёшгача | AJ6: 18 ёшдан катта | AL6: 18 ёшгача | AN6: 18 ёшдан катта | AQ6: Жами | AS6: телевидения | AU6: радио | AW6: газета | AY6: журнал | BA6: интернет (ижтимоий тармоқлар) | BC6: Жами | BE6: Видеоролик ва кон | BG6: Баннер | BI6: Флаер | BK6: Буклет | BM6: Бошқа | BO6: Пробация рўйғатида турувчи шахслар билан ўтказилган суҳбат
B7: сони | C7: бир кунда | D7: ой бошидан | E7: сони | F7: бир кунда | G7: ой бошидан | H7: сони | I7: бир кунда | J7: ой бошидан | K7: сони | L7: бир кунда | M7: ой бошидан | N7: сони | O7: бир кунда | P7: ой бошидан | Q7: сони | R7: бир кунда | S7: ой бошидан | T7: сони | U7: бир кунда | V7: ой бошидан | W7: сони | X7: бир кунда | Y7: ой бошидан | Z7: сони | AA7: бир кунда | AB7: ой бошидан | AC7: сони | AD7: бир кунда | AE7: ой бошидан | AF7: бир кунда | AG7: ой бошидан | AH7: бир кунда | AI7: ой бошидан | AJ7: бир кунда | AK7: ой бошидан | AL7: бир кунда | AM7: ой бошидан | AN7: бир кунда | AO7: ой бошидан | AQ7: бир кунда | AR7: ой бошидан | AS7: бир кунда | AT7: ой бошидан | AU7: бир кунда | AV7: ой бошидан | AW7: бир кунда | AX7: ой бошидан | AY7: бир кунда | AZ7: ой бошидан | BA7: бир кунда | BB7: ой бошидан | BC7: бир кунда | BD7: ой бошидан | BE7: бир кунда | BF7: ой бошидан | BG7: бир кунда | BH7: ой бошидан | BI7: бир кунда | BJ7: ой бошидан | BK7: бир кунда | BL7: ой бошидан | BM7: бир кунда | BN7: ой бошидан | BO7: Сони | BP7: бир кунда | BQ7: ой бошидан
A8: ИИВ | B8: =E8+H8+K8+N8+Q8+T8+W8+Z8+AC8 -> 0 | C8: =F8+I8+L8+O8+R8+U8+X8+AA8+AD8 -> 0 | D8: =G8+J8+M8+P8+S8+V8+Y8+AB8+AE8 -> 0 | G8: =F8 -> 0 | J8: =I8 -> 0 | M8: =L8 -> 0 | P8: =O8 -> 0 | S8: =R8 -> 0 | V8: =U8 -> 0 | Y8: =X8 -> 0 | AB8: =AA8 -> 0 | AE8: =AD8 -> 0 | AF8: =AH8+AJ8+AL8+AN8 -> 0 | AG8: =AI8+AK8+AM8+AO8 -> 0 | AI8: =AH8 -> 0 | AK8: =AJ8 -> 0 | AM8: =AL8 -> 0 | AO8: =AN8 -> 0 | AP8: ИИВ | AQ8: =AS8+AU8+AW8+AY8+BA8 -> 0 | AR8: =AT8+AV8+AX8+AZ8+BB8 -> 0 | AT8: =AS8 -> 0 | AV8: =AU8 -> 0 | AX8: =AW8 -> 0 | AZ8: =AY8 -> 0 | BB8: =BA8 -> 0 | BC8: =BE8+BG8+BI8+BK8+BM8 -> 0 | BD8: =BF8+BH8+BJ8+BL8+BN8 -> 0 | BF8: =BE8 -> 0 | BH8: =BG8 -> 0 | BJ8: =BI8 -> 0 | BL8: =BK8 -> 0 | BQ8: =BP8 -> 0
A9: ҚКР | B9: =E9+H9+K9+N9+Q9+T9+W9+Z9+AC9 -> 3841 | C9: =F9+I9+L9+O9+R9+U9+X9+AA9+AD9 -> 0 | D9: =G9+J9+M9+P9+S9+V9+Y9+AB9+AE9 -> 0 | E9: 452 | G9: =F9 -> 0 | H9: 12 | J9: =I9 -> 0 | K9: 2 | M9: =L9 -> 0 | N9: 735 | P9: =O9 -> 0 | Q9: 502 | S9: =R9 -> 0 | T9: 197 | V9: =U9 -> 0 | W9: 47 | Y9: =X9 -> 0 | Z9: 34 | AB9: =AA9 -> 0 | AC9: 1860 | AE9: =AD9 -> 0 | AF9: =AH9+AJ9+AL9+AN9 -> 0 | AG9: =AI9+AK9+AM9+AO9 -> 0 | AI9: =AH9 -> 0 | AK9: =AJ9 -> 0 | AM9: =AL9 -> 0 | AO9: =AN9 -> 0 | AP9: ҚКР | AQ9: =AS9+AU9+AW9+AY9+BA9 -> 0 | AR9: =AT9+AV9+AX9+AZ9+BB9 -> 0 | AT9: =AS9 -> 0 | AV9: =AU9 -> 0 | AX9: =AW9 -> 0 | AZ9: =AY9 -> 0 | BB9: =BA9 -> 0 | BC9: =BE9+BG9+BI9+BK9+BM9 -> 0 | BD9: =BF9+BH9+BJ9+BL9+BN9 -> 0 | BF9: =BE9 -> 0 | BH9: =BG9 -> 0 | BJ9: =BI9 -> 0 | BL9: =BK9 -> 0 | BN9: =BM9 -> 0 | BO9: 14 | BQ9: =BP9 -> 0
A10: Тошкент шаҳри | B10: =E10+H10+K10+N10+Q10+T10+W10+Z10+AC10 -> 3627 | C10: =F10+I10+L10+O10+R10+U10+X10+AA10+AD10 -> 0 | D10: =G10+J10+M10+P10+S10+V10+Y10+AB10+AE10 -> 0 | E10: 585 | F10: 0 | G10: =F10 -> 0 | H10: 93 | I10: 0 | J10: =I10 -> 0 | K10: 34 | L10: 0 | M10: =L10 -> 0 | N10: 352 | O10: 0 | P10: =O10 -> 0 | Q10: 549 | R10: 0 | S10: =R10 -> 0 | T10: 198 | U10: 0 | V10: =U10 -> 0 | W10: 55 | X10: 0 | Y10: =X10 -> 0 | Z10: 71 | AA10: 0 | AB10: =AA10 -> 0 | AC10: 1690 | AD10: 0 | AE10: =AD10 -> 0 | AF10: =AH10+AJ10+AL10+AN10 -> 0 | AG10: =AI10+AK10+AM10+AO10 -> 0 | AH10: 0 | AI10: =AH10 -> 0 | AJ10: 0 | AK10: =AJ10 -> 0 | AL10: 0 | AM10: =AL10 -> 0 | AN10: 0 | AO10: =AN10 -> 0 | AP10: Тошкент шаҳри | AQ10: =AS10+AU10+AW10+AY10+BA10 -> 0 | AR10: =AT10+AV10+AX10+AZ10+BB10 -> 0 | AS10: 0 | AT10: =AS10 -> 0 | AU10: 0 | AV10: =AU10 -> 0 | AW10: 0 | AX10: =AW10 -> 0 | AY10: 0 | AZ10: =AY10 -> 0 | BA10: 0 | BB10: =BA10 -> 0 | BC10: =BE10+BG10+BI10+BK10+BM10 -> 0 | BD10: =BF10+BH10+BJ10+BL10+BN10 -> 0 | BE10: 0 | BF10: =BE10 -> 0 | BG10: 0 | BH10: =BG10 -> 0 | BI10: 0 | BJ10: =BI10 -> 0 | BK10: 0 | BL10: =BK10 -> 0 | BM10: 0 | BN10: =BM10 -> 0 | BO10: 32 | BP10: 0 | BQ10: =BP10 -> 0
A11: Тошкент вилояти | B11: =E11+H11+K11+N11+Q11+T11+W11+Z11+AC11 -> 15381 | C11: =F11+I11+L11+O11+R11+U11+X11+AA11+AD11 -> 155 | D11: =G11+J11+M11+P11+S11+V11+Y11+AB11+AE11 -> 155 | E11: 883 | F11: 55 | G11: =F11 -> 55 | H11: 16 | I11: 0 | J11: =I11 -> 0 | K11: 3 | L11: 0 | M11: =L11 -> 0 | N11: 875 | O11: 0 | P11: =O11 -> 0 | Q11: 2424 | R11: 0 | S11: =R11 -> 0 | T11: 69 | U11: 0 | V11: =U11 -> 0 | W11: 133 | X11: 91 | Y11: =X11 -> 91 | Z11: 1116 | AA11: 0 | AB11: =AA11 -> 0 | AC11: 9862 | AD11: 9 | AE11: =AD11 -> 9 | AF11: =AH11+AJ11+AL11+AN11 -> 173200 | AG11: =AI11+AK11+AM11+AO11 -> 173200 | AH11: 6200 | AI11: =AH11 -> 6200 | AJ11: 9000 | AK11: =AJ11 -> 9000 | AL11: 53000 | AM11: =AL11 -> 53000 | AN11: 105000 | AO11: =AN11 -> 105000 | AP11: Тошкент вилояти | AQ11: =AS11+AU11+AW11+AY11+BA11 -> 11 | AR11: =AT11+AV11+AX11+AZ11+BB11 -> 11 | AS11: 0 | AT11: =AS11 -> 0 | AU11: 0 | AV11: =AU11 -> 0 | AW11: 0 | AX11: 0 | AY11: 0 | AZ11: =AY11 -> 0 | BA11: 11 | BB11: =BA11 -> 11 | BC11: =BE11+BG11+BI11+BK11+BM11 -> 6343 | BD11: =BF11+BH11+BJ11+BL11+BN11 -> 6343 | BE11: 12 | BF11: =BE11 -> 12 | BG11: 6 | BH11: =BG11 -> 6 | BI11: 6200 | BJ11: =BI11 -> 6200 | BK11: 125 | BL11: =BK11 -> 125 | BM11: 0 | BN11: =BM11 -> 0 | BO11: 11506 | BP11: 8 | BQ11: =BP11 -> 8
A12: Андижон вилояти | B12: =E12+H12+K12+N12+Q12+T12+W12+Z12+AC12 -> 30164 | C12: =F12+I12+L12+O12+R12+U12+X12+AA12+AD12 -> 237 | D12: =G12+J12+M12+P12+S12+V12+Y12+AB12+AE12 -> 237 | E12: 909 | F12: 48 | G12: =F12 -> 48 | H12: 80 | I12: 5 | J12: =I12 -> 5 | K12: 5 | L12: 0 | M12: =L12 -> 0 | N12: 820 | O12: 22 | P12: =O12 -> 22 | Q12: 549 | R12: 0 | S12: =R12 -> 0 | T12: 992 | U12: 0 | V12: =U12 -> 0 | W12: 38 | X12: 131 | Y12: =X12 -> 131 | Z12: 68 | AA12: 0 | AB12: =AA12 -> 0 | AC12: 26703 | AD12: 31 | AE12: =AD12 -> 31 | AF12: =AH12+AJ12+AL12+AN12 -> 30200 | AG12: =AI12+AK12+AM12+AO12 -> 30200 | AH12: 8000 | AI12: =AH12 -> 8000 | AJ12: 9500 | AK12: =AJ12 -> 9500 | AL12: 6350 | AM12: =AL12 -> 6350 | AN12: 6350 | AO12: =AN12 -> 6350 | AP12: Андижон вилояти | AQ12: =AS12+AU12+AW12+AY12+BA12 -> 128 | AR12: =AT12+AV12+AX12+AZ12+BB12 -> 128 | AS12: 0 | AT12: =AS12 -> 0 | AU12: 0 | AV12: =AU12 -> 0 | AW12: 0 | AX12: =AW12 -> 0 | AY12: 0 | AZ12: =AY12 -> 0 | BA12: 128 | BB12: =BA12 -> 128 | BC12: =BE12+BG12+BI12+BK12+BM12 -> 3802 | BD12: =BF12+BH12+BJ12+BL12+BN12 -> 3802 | BE12: 89 | BF12: =BE12 -> 89 | BG12: 13 | BH12: =BG12 -> 13 | BI12: 3200 | BJ12: =BI12 -> 3200 | BK12: 500 | BL12: =BK12 -> 500 | BM12: 0 | BN12: =BM12 -> 0 | BP12: 2 | BQ12: =BP12 -> 2
A13: Бухоро вилояти | B13: =E13+H13+K13+N13+Q13+T13+W13+Z13+AC13 -> 2044 | C13: =F13+I13+L13+O13+R13+U13+X13+AA13+AD13 -> 5 | D13: =G13+J13+M13+P13+S13+V13+Y13+AB13+AE13 -> 5 | E13: 516 | F13: 2 | G13: =F13 -> 2 | H13: 10 | I13: 0 | J13: =I13 -> 0 | K13: 38 | L13: 0 | M13: =L13 -> 0 | N13: 581 | O13: 1 | P13: =O13 -> 1 | Q13: 525 | R13: 0 | S13: =R13 -> 0 | T13: 263 | U13: 0 | V13: =U13 -> 0 | W13: 43 | X13: 0 | Y13: =X13 -> 0 | Z13: 17 | AA13: 0 | AB13: =AA13 -> 0 | AC13: 51 | AD13: 2 | AE13: =AD13 -> 2 | AF13: =AH13+AJ13+AL13+AN13 -> 228000 | AG13: =AI13+AK13+AM13+AO13 -> 228000 | AH13: 700 | AI13: =AH13 -> 700 | AJ13: 7300 | AK13: =AJ13 -> 7300 | AL13: 20000 | AM13: =AL13 -> 20000 | AN13: 200000 | AO13: =AN13 -> 200000 | AP13: Бухоро вилояти | AQ13: =AS13+AU13+AW13+AY13+BA13 -> 12 | AR13: =AT13+AV13+AX13+AZ13+BB13 -> 12 | AS13: 1 | AT13: =AS13 -> 1 | AU13: 1 | AV13: =AU13 -> 1 | AW13: 0 | AX13: =AW13 -> 0 | AY13: 0 | AZ13: =AY13 -> 0 | BA13: 10 | BB13: =BA13 -> 10 | BC13: =BE13+BG13+BI13+BK13+BM13 -> 8304 | BD13: =BF13+BH13+BJ13+BL13+BN13 -> 8304 | BE13: 200 | BF13: =BE13 -> 200 | BG13: 4 | BH13: =BG13 -> 4 | BI13: 8000 | BJ13: =BI13 -> 8000 | BK13: 100 | BL13: =BK13 -> 100 | BM13: 0 | BN13: =BM13 -> 0 | BP13: 1 | BQ13: =BP13 -> 1
A14: Жиззах вилояти | B14: =E14+H14+K14+N14+Q14+T14+W14+Z14+AC14 -> 3916 | C14: =F14+I14+L14+O14+R14+U14+X14+AA14+AD14 -> 146 | D14: =G14+J14+M14+P14+S14+V14+Y14+AB14+AE14 -> 146 | E14: 304 | F14: 117 | G14: =F14 -> 117 | H14: 5 | I14: 0 | J14: =I14 -> 0 | K14: 34 | L14: 0 | M14: =L14 -> 0 | N14: 583 | O14: 0 | P14: =O14 -> 0 | Q14: 254 | R14: 0 | S14: =R14 -> 0 | T14: 196 | U14: 0 | V14: =U14 -> 0 | W14: 30 | X14: 25 | Y14: =X14 -> 25 | Z14: 10 | AA14: 0 | AB14: =AA14 -> 0 | AC14: 2500 | AD14: 4 | AE14: =AD14 -> 4 | AF14: =AH14+AJ14+AL14+AN14 -> 190290 | AG14: =AI14+AK14+AM14+AO14 -> 190290 | AH14: 1420 | AI14: =AH14 -> 1420 | AJ14: 12520 | AK14: =AJ14 -> 12520 | AL14: 11220 | AM14: =AL14 -> 11220 | AN14: 165130 | AO14: =AN14 -> 165130 | AP14: Жиззах вилояти | AQ14: =AS14+AU14+AW14+AY14+BA14 -> 12 | AR14: =AT14+AV14+AX14+AZ14+BB14 -> 12 | AS14: 1 | AT14: =AS14 -> 1 | AU14: 0 | AV14: 0 | AW14: 1 | AX14: =AW14 -> 1 | AY14: 0 | AZ14: =AY14 -> 0 | BA14: 10 | BB14: =BA14 -> 10 | BC14: =BE14+BG14+BI14+BK14+BM14 -> 5302 | BD14: =BF14+BH14+BJ14+BL14+BN14 -> 5302 | BE14: 12 | BF14: =BE14 -> 12 | BG14: 5 | BH14: =BG14 -> 5 | BI14: 5240 | BJ14: =BI14 -> 5240 | BK14: 45 | BL14: =BK14 -> 45 | BM14: 0 | BN14: =BM14 -> 0 | BO14: 2 | BP14: 1 | BQ14: =BP14 -> 1
A15: Қашқадарё вилояти | B15: =E15+H15+K15+N15+Q15+T15+W15+Z15+AC15 -> 3897 | C15: =F15+I15+L15+O15+R15+U15+X15+AA15+AD15 -> 496 | D15: =G15+J15+M15+P15+S15+V15+Y15+AB15+AE15 -> 496 | E15: 776 | F15: 316 | G15: =F15 -> 316 | H15: 9 | I15: 0 | J15: =I15 -> 0 | K15: 6 | L15: 0 | M15: =L15 -> 0 | N15: 1305 | O15: 0 | P15: =O15 -> 0 | Q15: 447 | R15: 0 | S15: =R15 -> 0 | T15: 337 | U15: 0 | V15: =U15 -> 0 | W15: 78 | X15: 0 | Y15: =X15 -> 0 | Z15: 141 | AA15: 0 | AB15: =AA15 -> 0 | AC15: 798 | AD15: 180 | AE15: =AD15 -> 180 | AF15: =AH15+AJ15+AL15+AN15 -> 1571173 | AG15: =AI15+AK15+AM15+AO15 -> 1565673 | AH15: 1049 | AI15: =AH15 -> 1049 | AJ15: 5500 | AK15: 0 | AL15: 782312 | AM15: =AL15 -> 782312 | AN15: 782312 | AO15: =AN15 -> 782312 | AP15: Қашқадарё вилояти | AQ15: =AS15+AU15+AW15+AY15+BA15 -> 4 | AR15: =AT15+AV15+AX15+AZ15+BB15 -> 4 | AS15: 0 | AT15: =AS15 -> 0 | AU15: 0 | AV15: =AU15 -> 0 | AW15: 0 | AX15: =AW15 -> 0 | AY15: 0 | AZ15: =AY15 -> 0 | BA15: 4 | BB15: =BA15 -> 4 | BC15: =BE15+BG15+BI15+BK15+BM15 -> 4494 | BD15: =BF15+BH15+BJ15+BL15+BN15 -> 4494 | BE15: 88 | BF15: =BE15 -> 88 | BG15: 6 | BH15: =BG15 -> 6 | BI15: 2200 | BJ15: =BI15 -> 2200 | BK15: 2200 | BL15: =BK15 -> 2200 | BM15: 0 | BN15: =BM15 -> 0 | BO15: 6274 | BP15: 2 | BQ15: =BP15 -> 2 | BR15: умумий утирганлар билан
A16: Навоий вилояти | B16: =E16+H16+K16+N16+Q16+T16+W16+Z16+AC16 -> 19901 | C16: =F16+I16+L16+O16+R16+U16+X16+AA16+AD16 -> 154 | D16: =G16+J16+M16+P16+S16+V16+Y16+AB16+AE16 -> 154 | E16: 310 | F16: 61 | G16: =F16 -> 61 | H16: 5 | I16: 0 | J16: =I16 -> 0 | K16: 3 | L16: 0 | M16: =L16 -> 0 | N16: 384 | O16: 0 | P16: =O16 -> 0 | Q16: 245 | R16: 0 | S16: =R16 -> 0 | T16: 397 | U16: 0 | V16: =U16 -> 0 | W16: 24 | X16: 36 | Y16: =X16 -> 36 | Z16: 18 | AA16: 0 | AB16: =AA16 -> 0 | AC16: 18515 | AD16: 57 | AE16: =AD16 -> 57 | AF16: =AH16+AJ16+AL16+AN16 -> 65462 | AG16: =AI16+AK16+AM16+AO16 -> 65462 | AH16: 316 | AI16: =AH16 -> 316 | AJ16: 1226 | AK16: =AJ16 -> 1226 | AL16: 4230 | AM16: =AL16 -> 4230 | AN16: 59690 | AO16: =AN16 -> 59690 | AP16: Навоий вилояти | AQ16: =AS16+AU16+AW16+AY16+BA16 -> 75 | AR16: =AT16+AV16+AX16+AZ16+BB16 -> 75 | AS16: 0 | AT16: =AS16 -> 0 | AU16: 0 | AV16: =AU16 -> 0 | AW16: 0 | AX16: =AW16 -> 0 | AY16: 0 | AZ16: =AY16 -> 0 | BA16: 75 | BB16: =BA16 -> 75 | BC16: =BE16+BG16+BI16+BK16+BM16 -> 1567 | BD16: =BF16+BH16+BJ16+BL16+BN16 -> 1567 | BE16: 85 | BF16: =BE16 -> 85 | BG16: 2 | BH16: =BG16 -> 2 | BI16: 1230 | BJ16: =BI16 -> 1230 | BK16: 250 | BL16: =BK16 -> 250 | BM16: 0 | BN16: =BM16 -> 0 | BO16: 2546 | BP16: 0 | BQ16: =BP16 -> 0
A17: Наманган вилояти | B17: =E17+H17+K17+N17+Q17+T17+W17+Z17+AC17 -> 5602 | C17: =F17+I17+L17+O17+R17+U17+X17+AA17+AD17 -> 156 | D17: =G17+J17+M17+P17+S17+V17+Y17+AB17+AE17 -> 156 | E17: 754 | F17: 86 | G17: =F17 -> 86 | H17: 9 | I17: 0 | J17: =I17 -> 0 | K17: 5 | L17: 0 | M17: =L17 -> 0 | N17: 768 | O17: 0 | P17: =O17 -> 0 | Q17: 624 | R17: 0 | S17: =R17 -> 0 | T17: 742 | U17: 0 | V17: =U17 -> 0 | W17: 54 | X17: 0 | Y17: =X17 -> 0 | Z17: 66 | AA17: 0 | AB17: =AA17 -> 0 | AC17: 2580 | AD17: 70 | AE17: =AD17 -> 70 | AF17: =AH17+AJ17+AL17+AN17 -> 174300 | AG17: =AI17+AK17+AM17+AO17 -> 174300 | AH17: 9500 | AI17: =AH17 -> 9500 | AJ17: 9800 | AK17: =AJ17 -> 9800 | AL17: 80000 | AM17: =AL17 -> 80000 | AN17: 75000 | AO17: =AN17 -> 75000 | AP17: Наманган вилояти | AQ17: =AS17+AU17+AW17+AY17+BA17 -> 15 | AR17: =AT17+AV17+AX17+AZ17+BB17 -> 15 | AS17: 1 | AT17: =AS17 -> 1 | AU17: 0 | AV17: =AU17 -> 0 | AW17: 0 | AX17: =AW17 -> 0 | AY17: 0 | AZ17: =AY17 -> 0 | BA17: 14 | BB17: =BA17 -> 14 | BC17: =BE17+BG17+BI17+BK17+BM17 -> 1392 | BD17: =BF17+BH17+BJ17+BL17+BN17 -> 1392 | BE17: 38 | BF17: =BE17 -> 38 | BG17: 4 | BH17: =BG17 -> 4 | BI17: 1200 | BJ17: =BI17 -> 1200 | BK17: 150 | BL17: =BK17 -> 150 | BM17: 0 | BN17: =BM17 -> 0 | BO17: 8022 | BP17: 0 | BQ17: =BP17 -> 0
A18: Самарқанд вилояти | B18: =E18+H18+K18+N18+Q18+T18+W18+Z18+AC18 -> 3791 | C18: =F18+I18+L18+O18+R18+U18+X18+AA18+AD18 -> 584 | D18: =G18+J18+M18+P18+S18+V18+Y18+AB18+AE18 -> 584 | E18: 1063 | F18: 411 | G18: =F18 -> 411 | H18: 19 | I18: 0 | J18: =I18 -> 0 | K18: 8 | L18: 0 | M18: =L18 -> 0 | N18: 1331 | O18: 0 | P18: =O18 -> 0 | Q18: 777 | R18: 0 | S18: =R18 -> 0 | T18: 318 | U18: 0 | V18: =U18 -> 0 | W18: 60 | X18: 173 | Y18: =X18 -> 173 | Z18: 72 | AA18: 0 | AB18: =AA18 -> 0 | AC18: 143 | AD18: 0 | AE18: =AD18 -> 0 | AF18: =AH18+AJ18+AL18+AN18 -> 418649 | AG18: =AI18+AK18+AM18+AO18 -> 418649 | AH18: 1210 | AI18: =AH18 -> 1210 | AJ18: 6014 | AK18: =AJ18 -> 6014 | AL18: 17255 | AM18: =AL18 -> 17255 | AN18: 394170 | AO18: =AN18 -> 394170 | AP18: Самарқанд вилояти | AQ18: =AS18+AU18+AW18+AY18+BA18 -> 16 | AR18: =AT18+AV18+AX18+AZ18+BB18 -> 16 | AS18: 1 | AT18: =AS18 -> 1 | AU18: 0 | AV18: 0 | AW18: 0 | AX18: =AW18 -> 0 | AY18: 0 | AZ18: =AY18 -> 0 | BA18: 15 | BB18: =BA18 -> 15 | BC18: =BE18+BG18+BI18+BK18+BM18 -> 5569 | BD18: =BF18+BH18+BJ18+BL18+BN18 -> 5569 | BE18: 0 | BF18: =BE18 -> 0 | BG18: 0 | BH18: =BG18 -> 0 | BI18: 5215 | BJ18: =BI18 -> 5215 | BK18: 354 | BL18: =BK18 -> 354 | BM18: 0 | BN18: =BM18 -> 0 | BO18: 442 | BP18: 0 | BQ18: =BP18 -> 0
A19: Сирдарё вилояти | B19: =E19+H19+K19+N19+Q19+T19+W19+Z19+AC19 -> 1040 | C19: =F19+I19+L19+O19+R19+U19+X19+AA19+AD19 -> 28 | D19: =G19+J19+M19+P19+S19+V19+Y19+AB19+AE19 -> 28 | E19: 221 | F19: 8 | G19: =F19 -> 8 | H19: 5 | I19: 0 | J19: =I19 -> 0 | K19: 4 | L19: 0 | M19: =L19 -> 0 | N19: 313 | O19: 0 | P19: =O19 -> 0 | Q19: 203 | R19: 0 | S19: =R19 -> 0 | T19: 241 | U19: 0 | V19: =U19 -> 0 | W19: 14 | X19: 7 | Y19: =X19 -> 7 | Z19: 7 | AA19: 0 | AB19: =AA19 -> 0 | AC19: 32 | AD19: 13 | AE19: =AD19 -> 13 | AF19: =AH19+AJ19+AL19+AN19 -> 4000 | AG19: =AI19+AK19+AM19+AO19 -> 4000 | AH19: 600 | AI19: =AH19 -> 600 | AJ19: 600 | AK19: =AJ19 -> 600 | AL19: 1400 | AM19: =AL19 -> 1400 | AN19: 1400 | AO19: =AN19 -> 1400 | AP19: Сирдарё вилояти | AQ19: =AS19+AU19+AW19+AY19+BA19 -> 0 | AR19: =AT19+AV19+AX19+AZ19+BB19 -> 0 | AT19: =AS19 -> 0 | AV19: =AU19 -> 0 | AX19: =AW19 -> 0 | AZ19: =AY19 -> 0 | BB19: =BA19 -> 0 | BC19: =BE19+BG19+BI19+BK19+BM19 -> 0 | BD19: =BF19+BH19+BJ19+BL19+BN19 -> 0 | BF19: =BE19 -> 0 | BH19: =BG19 -> 0 | BJ19: =BI19 -> 0 | BL19: =BK19 -> 0 | BN19: =BM19 -> 0 | BO19: 2898 | BQ19: =BP19 -> 0
A20: Сурхондарё вилояти | B20: =E20+H20+K20+N20+Q20+T20+W20+Z20+AC20 -> 5228 | C20: =F20+I20+L20+O20+R20+U20+X20+AA20+AD20 -> 375 | D20: =G20+J20+M20+P20+S20+V20+Y20+AB20+AE20 -> 375 | E20: 723 | F20: 219 | G20: =F20 -> 219 | H20: 5 | I20: 1 | J20: =I20 -> 1 | K20: 3 | L20: 0 | M20: =L20 -> 0 | N20: 975 | O20: 80 | P20: =O20 -> 80 | Q20: 1862 | R20: 4 | S20: =R20 -> 4 | T20: 35 | U20: 4 | V20: =U20 -> 4 | W20: 64 | X20: 6 | Y20: =X20 -> 6 | Z20: 15 | AA20: 1 | AB20: =AA20 -> 1 | AC20: 1546 | AD20: 60 | AE20: =AD20 -> 60 | AF20: =AH20+AJ20+AL20+AN20 -> 13980 | AG20: =AI20+AK20+AM20+AO20 -> 13980 | AH20: 5890 | AI20: =AH20 -> 5890 | AJ20: 7490 | AK20: =AJ20 -> 7490 | AL20: 450 | AM20: =AL20 -> 450 | AN20: 150 | AO20: =AN20 -> 150 | AP20: Сурхондарё вилояти | AQ20: =AS20+AU20+AW20+AY20+BA20 -> 258 | AR20: =AT20+AV20+AX20+AZ20+BB20 -> 258 | AS20: 1 | AT20: =AS20 -> 1 | AU20: 1 | AV20: =AU20 -> 1 | AW20: 1 | AX20: =AW20 -> 1 | AZ20: =AY20 -> 0 | BA20: 255 | BB20: =BA20 -> 255 | BC20: =BE20+BG20+BI20+BK20+BM20 -> 2544 | BD20: =BF20+BH20+BJ20+BL20+BN20 -> 2544 | BE20: 4 | BF20: =BE20 -> 4 | BH20: =BG20 -> 0 | BI20: 1250 | BJ20: =BI20 -> 1250 | BK20: 1290 | BL20: =BK20 -> 1290 | BN20: =BM20 -> 0 | BO20: 5854 | BQ20: =BP20 -> 0 | BR20: 1862 та давлатники | BU20: 1302 та хусусий
A21: Фарғона | B21: =E21+H21+K21+N21+Q21+T21+W21+Z21+AC21 -> 3266 | C21: =F21+I21+L21+O21+R21+U21+X21+AA21+AD21 -> 226 | D21: =G21+J21+M21+P21+S21+V21+Y21+AB21+AE21 -> 226 | E21: 1017 | F21: 220 | G21: =F21 -> 220 | H21: 8 | I21: 5 | J21: =I21 -> 5 | K21: 4 | L21: 0 | M21: =L21 -> 0 | N21: 963 | O21: 0 | P21: =O21 -> 0 | Q21: 912 | R21: 0 | S21: =R21 -> 0 | T21: 199 | U21: 0 | V21: =U21 -> 0 | W21: 101 | X21: 0 | Y21: =X21 -> 0 | Z21: 42 | AA21: 0 | AB21: =AA21 -> 0 | AC21: 20 | AD21: 1 | AE21: =AD21 -> 1 | AF21: =AH21+AJ21+AL21+AN21 -> 260000 | AG21: =AI21+AK21+AM21+AO21 -> 260000 | AH21: 2000 | AI21: =AH21 -> 2000 | AJ21: 58000 | AK21: =AJ21 -> 58000 | AL21: 10000 | AM21: =AL21 -> 10000 | AN21: 190000 | AO21: =AN21 -> 190000 | AP21: Фарғона | AQ21: =AS21+AU21+AW21+AY21+BA21 -> 12 | AR21: =AT21+AV21+AX21+AZ21+BB21 -> 12 | AS21: 1 | AT21: =AS21 -> 1 | AU21: 4 | AV21: =AU21 -> 4 | AW21: 1 | AX21: =AW21 -> 1 | AY21: 0 | AZ21: =AY21 -> 0 | BA21: 6 | BB21: =BA21 -> 6 | BC21: =BE21+BG21+BI21+BK21+BM21 -> 9 | BD21: =BF21+BH21+BJ21+BL21+BN21 -> 9 | BE21: 4 | BF21: =BE21 -> 4 | BG21: 0 | BH21: =BG21 -> 0 | BI21: 4 | BJ21: =BI21 -> 4 | BK21: 0 | BL21: =BK21 -> 0 | BM21: 1 | BN21: =BM21 -> 1 | BQ21: =BP21 -> 0
A22: Хоразм | B22: =E22+H22+K22+N22+Q22+T22+W22+Z22+AC22 -> 1787 | C22: =F22+I22+L22+O22+R22+U22+X22+AA22+AD22 -> 1953 | D22: =G22+J22+M22+P22+S22+V22+Y22+AB22+AE22 -> 1953 | E22: 509 | F22: 422 | G22: =F22 -> 422 | H22: 8 | I22: 241 | J22: =I22 -> 241 | K22: 21 | M22: =L22 -> 0 | N22: 560 | P22: =O22 -> 0 | Q22: 375 | S22: =R22 -> 0 | T22: 165 | U22: 42 | V22: =U22 -> 42 | W22: 28 | X22: 90 | Y22: =X22 -> 90 | Z22: 9 | AB22: =AA22 -> 0 | AC22: 112 | AD22: 1158 | AE22: =AD22 -> 1158 | AF22: =AH22+AJ22+AL22+AN22 -> 993563 | AG22: =AI22+AK22+AM22+AO22 -> 993563 | AH22: 784 | AI22: =AH22 -> 784 | AJ22: 7238 | AK22: =AJ22 -> 7238 | AL22: 5412 | AM22: =AL22 -> 5412 | AN22: 980129 | AO22: =AN22 -> 980129 | AP22: Хоразм | AQ22: =AS22+AU22+AW22+AY22+BA22 -> 635 | AR22: =AT22+AV22+AX22+AZ22+BB22 -> 635 | AT22: =AS22 -> 0 | AV22: =AU22 -> 0 | AX22: =AW22 -> 0 | AZ22: =AY22 -> 0 | BA22: 635 | BB22: =BA22 -> 635 | BC22: =BE22+BG22+BI22+BK22+BM22 -> 6489 | BD22: =BF22+BH22+BJ22+BL22+BN22 -> 6489 | BE22: 31 | BF22: =BE22 -> 31 | BH22: =BG22 -> 0 | BI22: 6400 | BJ22: =BI22 -> 6400 | BK22: 58 | BL22: =BK22 -> 58 | BN22: =BM22 -> 0 | BO22: 26 | BP22: 226 | BQ22: =BP22 -> 226
A23: ЖАМИ | B23: =E23+H23+K23+N23+Q23+T23+W23+Z23+AC23 -> 94991 | C23: =F23+I23+L23+O23+R23+U23+X23+AA23+AD23 -> 4515 | D23: =G23+J23+M23+P23+S23+V23+Y23+AB23+AE23 -> 4515 | E23: =+E18+E19+E22+E17+E16+E15+E14+E13+E12+E11+E10+E9+E8 -> 7282 | F23: =SUM(F8:F22) -> 1965 | G23: =SUM(G8:G22) -> 1965 | H23: =+H18+H19+H22+H17+H16+H15+H14+H13+H12+H11+H10+H9+H8 -> 271 | I23: =SUM(I8:I22) -> 252 | J23: =SUM(J8:J22) -> 252 | K23: =+K18+K19+K22+K17+K16+K15+K14+K13+K12+K11+K10+K9+K8 -> 163 | L23: =SUM(L8:L22) -> 0 | M23: =SUM(M8:M22) -> 0 | N23: =+N18+N19+N22+N17+N16+N15+N14+N13+N12+N11+N10+N9+N8 -> 8607 | O23: =SUM(O8:O22) -> 103 | P23: =SUM(P8:P22) -> 103 | Q23: =+Q18+Q19+Q22+Q17+Q16+Q15+Q14+Q13+Q12+Q11+Q10+Q9+Q8 -> 7474 | R23: =SUM(R8:R22) -> 4 | S23: =SUM(S8:S22) -> 4 | T23: =+T18+T19+T22+T17+T16+T15+T14+T13+T12+T11+T10+T9+T8 -> 4115 | U23: =SUM(U8:U22) -> 46 | V23: =SUM(V8:V22) -> 46 | W23: =+W18+W19+W22+W17+W16+W15+W14+W13+W12+W11+W10+W9+W8 -> 604 | X23: =SUM(X8:X22) -> 559 | Y23: =SUM(Y8:Y22) -> 559 | Z23: =+Z18+Z19+Z22+Z17+Z16+Z15+Z14+Z13+Z12+Z11+Z10+Z9+Z8 -> 1629 | AA23: =SUM(AA8:AA22) -> 1 | AB23: =SUM(AB8:AB22) -> 1 | AC23: =+AC18+AC19+AC22+AC17+AC16+AC15+AC14+AC13+AC12+AC11+AC10+AC9+AC8 -> 64846 | AD23: =SUM(AD8:AD22) -> 1585 | AE23: =SUM(AE8:AE22) -> 1585 | AF23: =SUM(AF8:AF22) -> 4122817 | AG23: =SUM(AG8:AG22) -> 4117317 | AH23: =SUM(AH8:AH22) -> 37669 | AI23: =SUM(AI8:AI22) -> 37669 | AJ23: =SUM(AJ8:AJ22) -> 134188 | AK23: =SUM(AK8:AK22) -> 128688 | ... AO23: =SUM(AO8:AO22) -> 2959331 | AP23: ЖАМИ | AQ23: =SUM(AQ8:AQ22) -> 1178 | AR23: =SUM(AR8:AR22) -> 1178 | AS23: =SUM(AS8:AS22) -> 6 | AT23: =SUM(AT8:AT22) -> 6 | AU23: =SUM(AU8:AU22) -> 6 | AV23: =SUM(AV8:AV22) -> 6 | AW23: =SUM(AW8:AW22) -> 3 | AX23: =SUM(AX8:AX22) -> 3 | ... BQ23: =SUM(BQ8:BQ22) -> 240

Sheet 02.04
A1: Худудий бўлинмалар ходимлари томонидан ахборот технологиялари соҳасидаги жиноятларни олдини олиш бўйича амалга оширилган ишлар | AP1: Худудий бўлинмалар ходимлари томонидан ахборот технологиялари соҳасидаги жиноятларни олдини олиш бўйича амалга оширилган ишлар
A2: Ҳ И С О Б О Т Ж А Д В А Л И | AP2: ҲИСОБОТ ЖАДВАЛИ
A3: 1-жадвал 01.03.2026 йил | AP3: 2-жадвал 01.03.2026 йил
A4: Худудлар | B4: Ўтказилган учрашувлар сони март ойи учун | AF4: Учрашувда иштирок этган фуқаролар сони | AP4: Худудлар | AQ4: Оммавий ахборот воситаларида чиқишлар сони | BC4: Тарқатилган материаллар | BO4: Суҳбатлар
B5: ЖАМИ | E5: маҳаллалар | H5: олий таълим муассасалари | K5: академик лицейлар | N5: ўрта таълим муассасалари | Q5: мактабгача таълим муассасалари | T5: касалхона ва поликлиника | W5: бозорлар | Z5: ҲМҚОрганлари | AC5: бошқа идора ва ташкилотлар | AF5: ЖАМИ | AH5: учрашувлар давомида | AL5: Онлайн тарғибот давомида
AH6: 18 ёшгача | AJ6: 18 ёшдан катта | AL6: 18 ёшгача | AN6: 18 ёшдан катта | AQ6: Жами | AS6: телевидения | AU6: радио | AW6: газета | AY6: журнал | BA6: интернет (ижтимоий тармоқлар) | BC6: Жами | BE6: Видео ва конт | BG6: Баннер | BI6: Флаер | BK6: Буклет | BM6: Бошқа | BO6: Пробация рўйғатида турувчи шахслар билан ўтказилган суҳбат
B7: сони | C7: бир кунда | D7: ой бошидан | E7: сони | F7: бир кунда | G7: ой бошидан | H7: сони | I7: бир кунда | J7: ой бошидан | K7: сони | L7: бир кунда | M7: ой бошидан | N7: сони | O7: бир кунда | P7: ой бошидан | Q7: сони | R7: бир кунда | S7: ой бошидан | T7: сони | U7: бир кунда | V7: ой бошидан | W7: сони | X7: бир кунда | Y7: ой бошидан | Z7: сони | AA7: бир кунда | AB7: ой бошидан | AC7: сони | AD7: бир кунда | AE7: ой бошидан | AF7: бир кунда | AG7: ой бошидан | AH7: бир кунда | AI7: ой бошидан | AJ7: бир кунда | AK7: ой бошидан | AL7: бир кунда | AM7: ой бошидан | AN7: бир кунда | AO7: ой бошидан | AQ7: бир кунда | AR7: ой бошидан | AS7: бир кунда | AT7: ой бошидан | AU7: бир кунда | AV7: ой бошидан | AW7: бир кунда | AX7: ой бошидан | AY7: бир кунда | AZ7: ой бошидан | BA7: бир кунда | BB7: ой бошидан | BC7: бир кунда | BD7: ой бошидан | BE7: бир кунда | BF7: ой бошидан | BG7: бир кунда | BH7: ой бошидан | BI7: бир кунда | BJ7: ой бошидан | BK7: бир кунда | BL7: ой бошидан | BM7: бир кунда | BN7: ой бошидан | BO7: Сони | BP7: бир кунда | BQ7: ой бошидан
A8: ИИВ | B8: =E8+H8+K8+N8+Q8+T8+W8+Z8+AC8 -> 0 | C8: =F8+I8+L8+O8+R8+U8+X8+AA8+AD8 -> 0 | D8: =G8+J8+M8+P8+S8+V8+Y8+AB8+AE8 -> 0 | G8: =F8 -> 0 | J8: =I8 -> 0 | M8: =L8 -> 0 | P8: =O8 -> 0 | S8: =R8 -> 0 | V8: =U8 -> 0 | Y8: =X8 -> 0 | AB8: =AA8 -> 0 | AE8: =AD8 -> 0 | AF8: =AH8+AJ8+AL8+AN8 -> 0 | AG8: =AI8+AK8+AM8+AO8 -> 0 | AI8: =AH8 -> 0 | AK8: =AJ8 -> 0 | AM8: =AL8 -> 0 | AO8: =AN8 -> 0 | AP8: ИИВ | AQ8: =AS8+AU8+AW8+AY8+BA8 -> 0 | AR8: =AT8+AV8+AX8+AZ8+BB8 -> 0 | AT8: =AS8 -> 0 | AV8: =AU8 -> 0 | AX8: =AW8 -> 0 | AZ8: =AY8 -> 0 | BB8: =BA8 -> 0 | BC8: =BE8+BG8+BI8+BK8+BM8 -> 0 | BD8: =BF8+BH8+BJ8+BL8+BN8 -> 0 | BF8: =BE8 -> 0 | BH8: =BG8 -> 0 | BJ8: =BI8 -> 0 | BL8: =BK8 -> 0 | BQ8: =BP8 -> 0
A9: ҚКР | B9: =E9+H9+K9+N9+Q9+T9+W9+Z9+AC9 -> 3841 | C9: =F9+I9+L9+O9+R9+U9+X9+AA9+AD9 -> 4 | D9: =G9+J9+M9+P9+S9+V9+Y9+AB9+AE9 -> #REF! | E9: 452 | F9: 2 | G9: =F9+'01.04'!G9 -> #REF! | H9: 12 | I9: 1 | J9: =I9+'01.04'!J9 -> #REF! | K9: 2 | L9: 0 | M9: =L9+'01.04'!M9 -> #REF! | N9: 735 | O9: 0 | P9: =O9+'01.04'!P9 -> #REF! | Q9: 502 | R9: 0 | S9: =R9+'01.04'!S9 -> #REF! | T9: 197 | U9: 0 | V9: =U9+'01.04'!V9 -> #REF! | W9: 47 | X9: 1 | Y9: =X9+'01.04'!Y9 -> #REF! | Z9: 34 | AA9: 0 | AB9: =AA9+'01.04'!AB9 -> #REF! | AC9: 1860 | AD9: 0 | AE9: =AD9+'01.04'!AE9 -> #REF! | AF9: =AH9+AJ9+AL9+AN9 -> 8546 | AG9: =AI9+AK9+AM9+AO9 -> #REF! | AH9: 64 | AI9: =AH9+'01.04'!AI9 -> #REF! | AJ9: 282 | AK9: =AJ9+'01.04'!AK9 -> #REF! | AL9: 1800 | AM9: =AL9+'01.04'!AM9 -> #REF! | AN9: 6400 | AO9: =AN9+'01.04'!AO9 -> #REF! | AP9: ҚКР | AQ9: =AS9+AU9+AW9+AY9+BA9 -> 64 | AR9: =AT9+AV9+AX9+AZ9+BB9 -> #REF! | AS9: 2 | AT9: =AS9+'01.04'!AT9 -> #REF! | AU9: 0 | AV9: =AU9+'01.04'!AV9 -> #REF! | AW9: 0 | AX9: =AW9+'01.04'!AX9 -> #REF! | AY9: 0 | AZ9: =AY9+'01.04'!AZ9 -> #REF! | BA9: 62 | BB9: =BA9+'01.04'!BB9 -> #REF! | BC9: =BE9+BG9+BI9+BK9+BM9 -> 451 | BD9: =BF9+BH9+BJ9+BL9+BN9 -> #REF! | BE9: 1 | BF9: =BE9+'01.04'!BF9 -> #REF! | BG9: 0 | BH9: =BG9+'01.04'!BH9 -> #REF! | BI9: 450 | BJ9: =BI9+'01.04'!BJ9 -> #REF! | BK9: 0 | BL9: =BK9+'01.04'!BL9 -> #REF! | BM9: 0 | BN9: =BM9+'01.04'!BN9 -> #REF! | BO9: 14 | BP9: 0 | BQ9: =BP9+'01.04'!BQ9 -> #REF!
A10: Тошкент шаҳри | B10: =E10+H10+K10+N10+Q10+T10+W10+Z10+AC10 -> 3627 | C10: =F10+I10+L10+O10+R10+U10+X10+AA10+AD10 -> 158 | D10: =G10+J10+M10+P10+S10+V10+Y10+AB10+AE10 -> #REF! | E10: 585 | F10: 12 | G10: =F10+'01.04'!G10 -> #REF! | H10: 93 | I10: 11 | J10: =I10+'01.04'!J10 -> #REF! | K10: 34 | L10: 0 | M10: =L10+'01.04'!M10 -> #REF! | N10: 352 | O10: 10 | P10: =O10+'01.04'!P10 -> #REF! | Q10: 549 | R10: 11 | S10: =R10+'01.04'!S10 -> #REF! | T10: 198 | U10: 7 | V10: =U10+'01.04'!V10 -> #REF! | W10: 55 | X10: 0 | Y10: =X10+'01.04'!Y10 -> #REF! | Z10: 71 | AA10: 1 | AB10: =AA10+'01.04'!AB10 -> #REF! | AC10: 1690 | AD10: 106 | AE10: =AD10+'01.04'!AE10 -> #REF! | AF10: =AH10+AJ10+AL10+AN10 -> 128444 | AG10: =AI10+AK10+AM10+AO10 -> #REF! | AH10: 1043 | AI10: =AH10+'01.04'!AI10 -> #REF! | AJ10: 5294 | AK10: =AJ10+'01.04'!AK10 -> #REF! | AL10: 21196 | AM10: =AL10+'01.04'!AM10 -> #REF! | AN10: 100911 | AO10: =AN10+'01.04'!AO10 -> #REF! | AP10: Тошкент шаҳри | AQ10: =AS10+AU10+AW10+AY10+BA10 -> 3 | AR10: =AT10+AV10+AX10+AZ10+BB10 -> #REF! | AS10: 0 | AT10: =AS10+'01.04'!AT10 -> #REF! | AU10: 1 | AV10: =AU10+'01.04'!AV10 -> #REF! | AW10: 0 | AX10: =AW10+'01.04'!AX10 -> #REF! | AY10: 0 | AZ10: =AY10+'01.04'!AZ10 -> #REF! | BA10: 2 | BB10: =BA10+'01.04'!BB10 -> #REF! | BC10: =BE10+BG10+BI10+BK10+BM10 -> 4778 | BD10: =BF10+BH10+BJ10+BL10+BN10 -> #REF! | BE10: 616 | BF10: =BE10+'01.04'!BF10 -> #REF! | BG10: 0 | BH10: =BG10+'01.04'!BH10 -> #REF! | BI10: 2996 | BJ10: =BI10+'01.04'!BJ10 -> #REF! | BK10: 1166 | BL10: =BK10+'01.04'!BL10 -> #REF! | BM10: 0 | BN10: =BM10+'01.04'!BN10 -> #REF! | BO10: 32 | BP10: 0 | BQ10: =BP10+'01.04'!BQ10 -> #REF!
A11: Тошкент вилояти | B11: =E11+H11+K11+N11+Q11+T11+W11+Z11+AC11 -> 15381 | C11: =F11+I11+L11+O11+R11+U11+X11+AA11+AD11 -> 123 | D11: =G11+J11+M11+P11+S11+V11+Y11+AB11+AE11 -> #REF! | E11: 883 | F11: 50 | G11: =F11+'01.04'!G11 -> #REF! | H11: 16 | I11: 0 | J11: =I11+'01.04'!J11 -> #REF! | K11: 3 | L11: 0 | M11: =L11+'01.04'!M11 -> #REF! | N11: 875 | O11: 0 | P11: =O11+'01.04'!P11 -> #REF! | Q11: 2424 | R11: 0 | S11: =R11+'01.04'!S11 -> #REF! | T11: 69 | U11: 0 | V11: =U11+'01.04'!V11 -> #REF! | W11: 133 | X11: 64 | Y11: =X11+'01.04'!Y11 -> #REF! | Z11: 1116 | AA11: 0 | AB11: =AA11+'01.04'!AB11 -> #REF! | AC11: 9862 | AD11: 9 | AE11: =AD11+'01.04'!AE11 -> #REF! | AF11: =AH11+AJ11+AL11+AN11 -> 134200 | AG11: =AI11+AK11+AM11+AO11 -> #REF! | AH11: 5000 | AI11: =AH11+'01.04'!AI11 -> #REF! | AJ11: 9200 | AK11: =AJ11+'01.04'!AK11 -> #REF! | AL11: 25000 | AM11: =AL11+'01.04'!AM11 -> #REF! | AN11: 95000 | AO11: =AN11+'01.04'!AO11 -> #REF! | AP11: Тошкент вилояти | AQ11: =AS11+AU11+AW11+AY11+BA11 -> 9 | AR11: =AT11+AV11+AX11+AZ11+BB11 -> #REF! | AS11: 0 | AT11: =AS11+'01.04'!AT11 -> #REF! | AU11: 0 | AV11: =AU11+'01.04'!AV11 -> #REF! | AW11: 0 | AX11: =AW11+'01.04'!AX11 -> #REF! | AY11: 0 | AZ11: =AY11+'01.04'!AZ11 -> #REF! | BA11: 9 | BB11: =BA11+'01.04'!BB11 -> #REF! | BC11: =BE11+BG11+BI11+BK11+BM11 -> 7625 | BD11: =BF11+BH11+BJ11+BL11+BN11 -> #REF! | BE11: 9 | BF11: =BE11+'01.04'!BF11 -> #REF! | BG11: 6 | BH11: =BG11+'01.04'!BH11 -> #REF! | BI11: 7500 | BJ11: =BI11+'01.04'!BJ11 -> #REF! | BK11: 110 | BL11: =BK11+'01.04'!BL11 -> #REF! | BM11: 0 | BN11: =BM11+'01.04'!BN11 -> #REF! | BO11: 11506 | BP11: 6 | BQ11: =BP11+'01.04'!BQ11 -> #REF!
A12: Андижон вилояти | B12: =E12+H12+K12+N12+Q12+T12+W12+Z12+AC12 -> 30164 | C12: =F12+I12+L12+O12+R12+U12+X12+AA12+AD12 -> 574 | D12: =G12+J12+M12+P12+S12+V12+Y12+AB12+AE12 -> #REF! | E12: 909 | F12: 201 | G12: =F12+'01.04'!G12 -> #REF! | H12: 80 | I12: 3 | J12: =I12+'01.04'!J12 -> #REF! | K12: 5 | L12: 0 | M12: =L12+'01.04'!M12 -> #REF! | N12: 820 | O12: 30 | P12: =O12+'01.04'!P12 -> #REF! | Q12: 549 | R12: 0 | S12: =R12+'01.04'!S12 -> #REF! | T12: 992 | U12: 0 | V12: =U12+'01.04'!V12 -> #REF! | W12: 38 | X12: 150 | Y12: =X12+'01.04'!Y12 -> #REF! | Z12: 68 | AA12: 0 | AB12: =AA12+'01.04'!AB12 -> #REF! | AC12: 26703 | AD12: 190 | AE12: =AD12+'01.04'!AE12 -> #REF! | AF12: =AH12+AJ12+AL12+AN12 -> 34090 | AG12: =AI12+AK12+AM12+AO12 -> #REF! | AH12: 7800 | AI12: =AH12+'01.04'!AI12 -> #REF! | AJ12: 10900 | AK12: =AJ12+'01.04'!AK12 -> #REF! | AL12: 7695 | AM12: =AL12+'01.04'!AM12 -> #REF! | AN12: 7695 | AO12: =AN12+'01.04'!AO12 -> #REF! | AP12: Андижон вилояти | AQ12: =AS12+AU12+AW12+AY12+BA12 -> 0 | AR12: =AT12+AV12+AX12+AZ12+BB12 -> #REF! | AS12: 0 | AT12: =AS12+'01.04'!AT12 -> #REF! | AU12: 0 | AV12: =AU12+'01.04'!AV12 -> #REF! | AW12: 0 | AX12: =AW12+'01.04'!AX12 -> #REF! | AY12: 0 | AZ12: =AY12+'01.04'!AZ12 -> #REF! | BA12: 0 | BB12: =BA12+'01.04'!BB12 -> #REF! | BC12: =BE12+BG12+BI12+BK12+BM12 -> 4307 | BD12: =BF12+BH12+BJ12+BL12+BN12 -> #REF! | BE12: 92 | BF12: =BE12+'01.04'!BF12 -> #REF! | BG12: 15 | BH12: =BG12+'01.04'!BH12 -> #REF! | BI12: 3500 | BJ12: =BI12+'01.04'!BJ12 -> #REF! | BK12: 700 | BL12: =BK12+'01.04'!BL12 -> #REF! | BM12: 0 | BN12: =BM12+'01.04'!BN12 -> #REF! | BP12: 1 | BQ12: =BP12+'01.04'!BQ12 -> #REF!
A13: Бухоро вилояти | B13: =E13+H13+K13+N13+Q13+T13+W13+Z13+AC13 -> 2044 | C13: =F13+I13+L13+O13+R13+U13+X13+AA13+AD13 -> 2 | D13: =G13+J13+M13+P13+S13+V13+Y13+AB13+AE13 -> #REF! | E13: 516 | F13: 1 | G13: =F13+'01.04'!G13 -> #REF! | H13: 10 | I13: 0 | J13: =I13+'01.04'!J13 -> #REF! | K13: 38 | L13: 0 | M13: =L13+'01.04'!M13 -> #REF! | N13: 581 | O13: 0 | P13: =O13+'01.04'!P13 -> #REF! | Q13: 525 | R13: 0 | S13: =R13+'01.04'!S13 -> #REF! | T13: 263 | U13: 1 | V13: =U13+'01.04'!V13 -> #REF! | W13: 43 | Y13: =X13+'01.04'!Y13 -> #REF! | Z13: 17 | AA13: 0 | AB13: =AA13+'01.04'!AB13 -> #REF! | AC13: 51 | AD13: 0 | AE13: =AD13+'01.04'!AE13 -> #REF! | AF13: =AH13+AJ13+AL13+AN13 -> 260100 | AG13: =AI13+AK13+AM13+AO13 -> #REF! | AH13: 2000 | AI13: =AH13+'01.04'!AI13 -> #REF! | AJ13: 8100 | AK13: =AJ13+'01.04'!AK13 -> #REF! | AL13: 30000 | AM13: =AL13+'01.04'!AM13 -> #REF! | AN13: 220000 | AO13: =AN13+'01.04'!AO13 -> #REF! | AP13: Бухоро вилояти | AQ13: =AS13+AU13+AW13+AY13+BA13 -> 21 | AR13: =AT13+AV13+AX13+AZ13+BB13 -> #REF! | AS13: 1 | AT13: =AS13+'01.04'!AT13 -> #REF! | AU13: 0 | AV13: =AU13+'01.04'!AV13 -> #REF! | AW13: 0 | AX13: =AW13+'01.04'!AX13 -> #REF! | AY13: 0 | AZ13: =AY13+'01.04'!AZ13 -> #REF! | BA13: 20 | BB13: =BA13+'01.04'!BB13 -> #REF! | BC13: =BE13+BG13+BI13+BK13+BM13 -> 10101 | BD13: =BF13+BH13+BJ13+BL13+BN13 -> #REF! | BE13: 1 | BF13: =BE13+'01.04'!BF13 -> #REF! | BG13: 0 | BH13: =BG13+'01.04'!BH13 -> #REF! | BI13: 10000 | BJ13: =BI13+'01.04'!BJ13 -> #REF! | BK13: 100 | BL13: =BK13+'01.04'!BL13 -> #REF! | BM13: 0 | BN13: =BM13+'01.04'!BN13 -> #REF! | BP13: 0 | BQ13: =BP13+'01.04'!BQ13 -> #REF!
A14: Жиззах вилояти | B14: =E14+H14+K14+N14+Q14+T14+W14+Z14+AC14 -> 3916 | C14: =F14+I14+L14+O14+R14+U14+X14+AA14+AD14 -> 105 | D14: =G14+J14+M14+P14+S14+V14+Y14+AB14+AE14 -> #REF! | E14: 304 | F14: 85 | G14: =F14+'01.04'!G14 -> #REF! | H14: 5 | I14: 0 | J14: =I14+'01.04'!J14 -> #REF! | K14: 34 | L14: 0 | M14: =L14+'01.04'!M14 -> #REF! | N14: 583 | O14: 0 | P14: =O14+'01.04'!P14 -> #REF! | Q14: 254 | R14: 0 | S14: =R14+'01.04'!S14 -> #REF! | T14: 196 | U14: 0 | V14: =U14+'01.04'!V14 -> #REF! | W14: 30 | X14: 15 | Y14: =X14+'01.04'!Y14 -> #REF! | Z14: 10 | AA14: 0 | AB14: =AA14+'01.04'!AB14 -> #REF! | AC14: 2500 | AD14: 5 | AE14: =AD14+'01.04'!AE14 -> #REF! | AF14: =AH14+AJ14+AL14+AN14 -> 149960 | AG14: =AI14+AK14+AM14+AO14 -> #REF! | AH14: 3420 | AI14: =AH14+'01.04'!AI14 -> #REF! | AJ14: 7000 | AK14: =AJ14+'01.04'!AK14 -> #REF! | AL14: 25540 | AM14: =AL14+'01.04'!AM14 -> #REF! | AN14: 114000 | AO14: =AN14+'01.04'!AO14 -> #REF! | AP14: Жиззах вилояти | AQ14: =AS14+AU14+AW14+AY14+BA14 -> 6 | AR14: =AT14+AV14+AX14+AZ14+BB14 -> #REF! | AS14: 0 | AT14: =AS14+'01.04'!AT14 -> #REF! | AU14: 0 | AV14: =AU14+'01.04'!AV14 -> #REF! | AW14: 0 | AX14: =AW14+'01.04'!AX14 -> #REF! | AY14: 0 | AZ14: =AY14+'01.04'!AZ14 -> #REF! | BA14: 6 | BB14: =BA14+'01.04'!BB14 -> #REF! | BC14: =BE14+BG14+BI14+BK14+BM14 -> 4540 | BD14: =BF14+BH14+BJ14+BL14+BN14 -> #REF! | BE14: 8 | BF14: =BE14+'01.04'!BF14 -> #REF! | BG14: 6 | BH14: =BG14+'01.04'!BH14 -> #REF! | BI14: 4500 | BJ14: =BI14+'01.04'!BJ14 -> #REF! | BK14: 26 | BL14: =BK14+'01.04'!BL14 -> #REF! | BM14: 0 | BN14: =BM14+'01.04'!BN14 -> #REF! | BO14: 2 | BP14: 0 | BQ14: =BP14+'01.04'!BQ14 -> #REF!
A15: Қашқадарё вилояти | B15: =E15+H15+K15+N15+Q15+T15+W15+Z15+AC15 -> 3897 | C15: =F15+I15+L15+O15+R15+U15+X15+AA15+AD15 -> 405 | D15: =G15+J15+M15+P15+S15+V15+Y15+AB15+AE15 -> #REF! | E15: 776 | F15: 267 | G15: =F15+'01.04'!G15 -> #REF! | H15: 9 | I15: 0 | J15: =I15+'01.04'!J15 -> #REF! | K15: 6 | L15: 0 | M15: =L15+'01.04'!M15 -> #REF! | N15: 1305 | O15: 0 | P15: =O15+'01.04'!P15 -> #REF! | Q15: 447 | R15: 0 | S15: =R15+'01.04'!S15 -> #REF! | T15: 337 | U15: 0 | V15: =U15+'01.04'!V15 -> #REF! | W15: 78 | X15: 0 | Y15: =X15+'01.04'!Y15 -> #REF! | Z15: 141 | AA15: 0 | AB15: =AA15+'01.04'!AB15 -> #REF! | AC15: 798 | AD15: 138 | AE15: =AD15+'01.04'!AE15 -> #REF! | AF15: =AH15+AJ15+AL15+AN15 -> 1220341 | AG15: =AI15+AK15+AM15+AO15 -> #REF! | AH15: 1087 | AI15: =AH15+'01.04'!AI15 -> #REF! | AJ15: 3900 | AK15: =AJ15+'01.04'!AK15 -> #REF! | AL15: 607677 | AM15: =AL15+'01.04'!AM15 -> #REF! | AN15: 607677 | AO15: =AN15+'01.04'!AO15 -> #REF! | AP15: Қашқадарё вилояти | AQ15: =AS15+AU15+AW15+AY15+BA15 -> 6 | AR15: =AT15+AV15+AX15+AZ15+BB15 -> #REF! | AS15: 0 | AT15: =AS15+'01.04'!AT15 -> #REF! | AU15: 0 | AV15: =AU15+'01.04'!AV15 -> #REF! | AW15: 0 | AX15: =AW15+'01.04'!AX15 -> #REF! | AY15: 0 | AZ15: =AY15+'01.04'!AZ15 -> #REF! | BA15: 6 | BB15: =BA15+'01.04'!BB15 -> #REF! | BC15: =BE15+BG15+BI15+BK15+BM15 -> 1864 | BD15: =BF15+BH15+BJ15+BL15+BN15 -> #REF! | BE15: 60 | BF15: =BE15+'01.04'!BF15 -> #REF! | BG15: 4 | BH15: =BG15+'01.04'!BH15 -> #REF! | BI15: 900 | BJ15: =BI15+'01.04'!BJ15 -> #REF! | BK15: 900 | BL15: =BK15+'01.04'!BL15 -> #REF! | BM15: 0 | BN15: =BM15+'01.04'!BN15 -> #REF! | BO15: 6274 | BP15: 2 | BQ15: =BP15+'01.04'!BQ15 -> #REF! | BR15: умумий утирганлар билан
